Workbook
Name A部门L1: [1]员工信息统计表!$I1

Sheet 汇总
A1: 创想悦动2026年7月工资汇总表
A2: 分类 | B2: 部门 | C2: 人数 | D2: 基本工资 | E2: 绩效工资 | F2: 岗位津贴 | G2: 节日福利 | H2: 通讯补贴 | I2: 考勤扣款 | J2: 其他扣款 | K2: 加班费 | L2: 绩效奖金 | M2: 其他奖金 | N2: 伙食补贴 | O2: 住房补贴 | P2: 司机补贴 | Q2: 专利奖 | R2: 其他补发 | S2: 补发合计 | T2: 应付工资 | U2: 借款逾期扣款 | V2: 房租水电 | W2: 房租水电1 | X2: 其他代扣款 | Y2: 扣款合计 | Z2: 养老保险 | AA2: 医疗保险 | AB2: 失业保险 | AC2: 住房公积金 | AD2: 所得税 | AE2: 实发工资
A3: 销售 | B3: 创想悦动-销售 | C3: =SUMIF(工资表明细!$J$2:$J$82,$B3,工资表明细!L$2:L$82) -> 14 | D3: =SUMIF(工资表明细!$J$3:$J$82,$B3,工资表明细!P$3:P$82) -> 246000 | E3: =SUMIF(工资表明细!$J$3:$J$82,$B3,工资表明细!Q$3:Q$82) -> 0 | F3: =SUMIF(工资表明细!$J$3:$J$82,$B3,工资表明细!R$3:R$82) -> 0 | G3: =SUMIF(工资表明细!$J$3:$J$82,$B3,工资表明细!S$3:S$82) -> 0 | H3: =SUMIF(工资表明细!$J$3:$J$82,$B3,工资表明细!T$3:T$82) -> 0 | I3: =SUMIF(工资表明细!$J$3:$J$82,$B3,工资表明细!U$3:U$82) -> 6206.9 | J3: =SUMIF(工资表明细!$J$3:$J$82,$B3,工资表明细!V$3:V$82) -> 0 | K3: =SUMIF(工资表明细!$J$3:$J$82,$B3,工资表明细!W$3:W$82) -> 0 | ... AC3: =SUMIF(工资表明细!$J$3:$J$82,$B3,工资表明细!AO$3:AO$82) -> 20480 | AD3: =SUMIF(工资表明细!$J$3:$J$82,$B3,工资表明细!BE$3:BE$82) -> 7179.72 | AE3: =SUMIF(工资表明细!$J$3:$J$82,$B3,工资表明细!BF$3:BF$82) -> 190569.54
B4: 小计 | C4: =SUM(C3:C3) -> 14 | D4: =SUM(D3:D3) -> 246000 | E4: =SUM(E3:E3) -> 0 | F4: =SUM(F3:F3) -> 0 | G4: =SUM(G3:G3) -> 0 | H4: =SUM(H3:H3) -> 0 | I4: =SUM(I3:I3) -> 6206.9 | J4: =SUM(J3:J3) -> 0 | ... AE4: =SUM(AE3:AE3) -> 190569.54
A5: 研发 | B5: 创想悦动-研发 | C5: =SUMIF(工资表明细!$J$2:$J$82,$B5,工资表明细!L$2:L$82) -> 55 | D5: =SUMIF(工资表明细!$J$3:$J$82,$B5,工资表明细!P$3:P$82) -> 1263300 | E5: =SUMIF(工资表明细!$J$3:$J$82,$B5,工资表明细!Q$3:Q$82) -> 0 | F5: =SUMIF(工资表明细!$J$3:$J$82,$B5,工资表明细!R$3:R$82) -> 0 | G5: =SUMIF(工资表明细!$J$3:$J$82,$B5,工资表明细!S$3:S$82) -> 0 | H5: =SUMIF(工资表明细!$J$3:$J$82,$B5,工资表明细!T$3:T$82) -> 0 | I5: =SUMIF(工资表明细!$J$3:$J$82,$B5,工资表明细!U$3:U$82) -> 43287.36 | J5: =SUMIF(工资表明细!$J$3:$J$82,$B5,工资表明细!V$3:V$82) -> 0 | K5: =SUMIF(工资表明细!$J$3:$J$82,$B5,工资表明细!W$3:W$82) -> 0 | ... AC5: =SUMIF(工资表明细!$J$3:$J$82,$B5,工资表明细!AO$3:AO$82) -> 88863.6 | AD5: =SUMIF(工资表明细!$J$3:$J$82,$B5,工资表明细!BE$3:BE$82) -> 85237.98 | AE5: =SUMIF(工资表明细!$J$3:$J$82,$B5,工资表明细!BF$3:BF$82) -> 932559.11
B6: 小计 | C6: =SUM(C5:C5) -> 55 | D6: =SUM(D5:D5) -> 1263300 | E6: =SUM(E5:E5) -> 0 | F6: =SUM(F5:F5) -> 0 | G6: =SUM(G5:G5) -> 0 | H6: =SUM(H5:H5) -> 0 | I6: =SUM(I5:I5) -> 43287.36 | J6: =SUM(J5:J5) -> 0 | ... AE6: =SUM(AE5:AE5) -> 932559.11
A7: 职能 | B7: 创想悦动-管理 | C7: =SUMIF(工资表明细!$J$2:$J$82,$B7,工资表明细!L$2:L$82) -> 9 | D7: =SUMIF(工资表明细!$J$3:$J$82,$B7,工资表明细!P$3:P$82) -> 281000 | E7: =SUMIF(工资表明细!$J$3:$J$82,$B7,工资表明细!Q$3:Q$82) -> 0 | F7: =SUMIF(工资表明细!$J$3:$J$82,$B7,工资表明细!R$3:R$82) -> 0 | G7: =SUMIF(工资表明细!$J$3:$J$82,$B7,工资表明细!S$3:S$82) -> 0 | H7: =SUMIF(工资表明细!$J$3:$J$82,$B7,工资表明细!T$3:T$82) -> 0 | I7: =SUMIF(工资表明细!$J$3:$J$82,$B7,工资表明细!U$3:U$82) -> 0 | J7: =SUMIF(工资表明细!$J$3:$J$82,$B7,工资表明细!V$3:V$82) -> 0 | K7: =SUMIF(工资表明细!$J$3:$J$82,$B7,工资表明细!W$3:W$82) -> 0 | ... AC7: =SUMIF(工资表明细!$J$3:$J$82,$B7,工资表明细!AO$3:AO$82) -> 21739.5 | AD7: =SUMIF(工资表明细!$J$3:$J$82,$B7,工资表明细!BE$3:BE$82) -> 34577.71 | AE7: =SUMIF(工资表明细!$J$3:$J$82,$B7,工资表明细!BF$3:BF$82) -> 206836.83
B8: 小计 | C8: =SUM(C7:C7) -> 9 | D8: =SUM(D7:D7) -> 281000 | E8: =SUM(E7:E7) -> 0 | F8: =SUM(F7:F7) -> 0 | G8: =SUM(G7:G7) -> 0 | H8: =SUM(H7:H7) -> 0 | I8: =SUM(I7:I7) -> 0 | J8: =SUM(J7:J7) -> 0 | ... AE8: =SUM(AE7:AE7) -> 206836.83
A9: 总计 | C9: =C4+C6+C8 -> 78 | D9: =D4+D6+D8 -> 1790300 | E9: =E4+E6+E8 -> 0 | F9: =F4+F6+F8 -> 0 | G9: =G4+G6+G8 -> 0 | H9: =H4+H6+H8 -> 0 | I9: =I4+I6+I8 -> 49494.26 | J9: =J4+J6+J8 -> 0 | ... AE9: =AE4+AE6+AE8 -> 1329965.5
C10: =C9-工资表明细!L83 -> 0 | D10: =D9-工资表明细!P83 -> 0 | E10: =E9-工资表明细!Q83 -> 0 | F10: =F9-工资表明细!R83 -> 0 | G10: =G9-工资表明细!S83 -> 0 | H10: =H9-工资表明细!T83 -> 0 | I10: =I9-工资表明细!U83 -> 0 | J10: =J9-工资表明细!V83 -> 0 | K10: =K9-工资表明细!W83 -> 0 | ... AC10: =AC9-工资表明细!AO83 -> 0 | AD10: =AD9-工资表明细!BE83 -> 0 | AE10: =AE9-工资表明细!BF83 -> 0

Sheet 环比变动
A1: 2026年7月创想悦动工资环比变动情况
A2: 年月 | B2: 项目 | C2: 人数 | D2: 基础工资 | E2: 绩效工资 | F2: 岗位津贴 | G2: 节日福利 | H2: 通讯补贴 | I2: 考勤扣款 | J2: 其他扣款 | K2: 加班费 | L2: 绩效奖金 | M2: 其他奖金 | N2: 伙食补贴 | O2: 住房补贴 | P2: 司机补贴 | Q2: 专利奖 | R2: 其他补发 | S2: 补发合计 | T2: 应付工资 | U2: 借款逾期扣款 | V2: 水电费 | W2: 房租 | X2: 其他代扣款 | Y2: 扣款合计 | Z2: 社保费 | AA2: 住房公积金 | AB2: 个人所得税 | AC2: 实发工资
A3: 46204 | B3: 职能 | C3: =汇总!C8 -> 9 | D3: =汇总!D8 -> 281000 | E3: =汇总!E8 -> 0 | F3: =汇总!F8 -> 0 | G3: =汇总!G8 -> 0 | H3: =汇总!H8 -> 0 | I3: =汇总!I8 -> 0 | J3: =汇总!J8 -> 0 | ... Y3: =汇总!Y8 -> -140.24 | Z3: =汇总!Z8+汇总!AA8+汇总!AB8 -> 17986.2 | AA3: =汇总!AC8 -> 21739.5 | AB3: =汇总!AD8 -> 34577.71 | AC3: =汇总!AE8 -> 206836.83
B4: 研发 | C4: =汇总!C6 -> 55 | D4: =汇总!D6 -> 1263300 | E4: =汇总!E6 -> 0 | F4: =汇总!F6 -> 0 | G4: =汇总!G6 -> 0 | H4: =汇总!H6 -> 0 | I4: =汇总!I6 -> 43287.36 | J4: =汇总!J6 -> 0 | ... Y4: =汇总!Y6 -> 1280.25 | Z4: =汇总!Z6+汇总!AA6+汇总!AB6 -> 112871.7 | AA4: =汇总!AC6 -> 88863.6 | AB4: =汇总!AD6 -> 85237.98 | AC4: =汇总!AE6 -> 932559.11
B5: 销售 | C5: =汇总!C4 -> 14 | D5: =汇总!D4 -> 246000 | E5: =汇总!E4 -> 0 | F5: =汇总!F4 -> 0 | G5: =汇总!G4 -> 0 | H5: =汇总!H4 -> 0 | I5: =汇总!I4 -> 6206.9 | J5: =汇总!J4 -> 0 | ... Y5: =汇总!Y4 -> -1840 | Z5: =汇总!Z4+汇总!AA4+汇总!AB4 -> 23403.84 | AA5: =汇总!AC4 -> 20480 | AB5: =汇总!AD4 -> 7179.72 | AC5: =汇总!AE4 -> 190569.54
B6: 合计 | C6: =SUM(C3:C5) -> 78 | D6: =SUM(D3:D5) -> 1790300 | E6: =SUM(E3:E5) -> 0 | F6: =SUM(F3:F5) -> 0 | G6: =SUM(G3:G5) -> 0 | H6: =SUM(H3:H5) -> 0 | I6: =SUM(I3:I5) -> 49494.26 | J6: =SUM(J3:J5) -> 0 | ... AC6: =SUM(AC3:AC5) -> 1329965.5
A7: 46174 | B7: 职能 | C7: 9 | D7: 281000 | E7: 0 | F7: 0 | G7: 0 | H7: 0 | I7: 1379.31 | J7: 0 | K7: 0 | L7: 0 | M7: 0 | N7: 0 | O7: 0 | P7: 0 | Q7: 0 | R7: 1800 | S7: 1800 | T7: 281420.69 | U7: 0 | V7: 0 | W7: 0 | X7: 1800 | Y7: 1800 | Z7: 17961.91 | AA7: 13487.7 | AB7: 34488.18 | AC7: 213682.9
B8: 研发 | C8: 55 | D8: 1244300 | E8: 0 | F8: 0 | G8: 0 | H8: 0 | I8: 145206.91 | J8: 0 | K8: 0 | L8: 0 | M8: 0 | N8: 0 | O8: 0 | P8: 0 | Q8: 0 | R8: 10800 | S8: 10800 | T8: 1109893.1 | U8: 0 | V8: 0 | W8: 0 | X8: 10800 | Y8: 10800 | Z8: 102917.69 | AA8: 66257.7 | AB8: 73910.59 | AC8: 856007.11
B9: 销售 | C9: 12 | D9: 214000 | E9: 0 | F9: 0 | G9: 0 | H9: 0 | I9: 34344.83 | J9: 0 | K9: 5655.17 | L9: 0 | M9: 0 | N9: 0 | O9: 0 | P9: 0 | Q9: 0 | R9: 2800 | S9: 8455.17 | T9: 188110.34 | U9: 0 | V9: 0 | W9: 0 | X9: 2800 | Y9: 2800 | Z9: 18119.92 | AA9: 10500 | AB9: 6181.46 | AC9: 150508.96
B10: 合计 | C10: =SUM(C7:C9) -> 76 | D10: =SUM(D7:D9) -> 1739300 | E10: =SUM(E7:E9) -> 0 | F10: =SUM(F7:F9) -> 0 | G10: =SUM(G7:G9) -> 0 | H10: =SUM(H7:H9) -> 0 | I10: =SUM(I7:I9) -> 180931.05 | J10: =SUM(J7:J9) -> 0 | ... AC10: =SUM(AC7:AC9) -> 1220199
A11: 变动 | B11: 职能 | C11: =C3-C7 -> 0 | D11: =D3-D7 -> 0 | E11: =E3-E7 -> 0 | F11: =F3-F7 -> 0 | G11: =G3-G7 -> 0 | H11: =H3-H7 -> 0 | I11: =I3-I7 -> -1379.31 | J11: =J3-J7 -> 0 | ... AC11: =AC3-AC7 -> -6846.07
B12: 研发 | C12: =C4-C8 -> 0 | D12: =D4-D8 -> 19000 | E12: =E4-E8 -> 0 | F12: =F4-F8 -> 0 | G12: =G4-G8 -> 0 | H12: =H4-H8 -> 0 | I12: =I4-I8 -> -101919.55 | J12: =J4-J8 -> 0 | ... AC12: =AC4-AC8 -> 76552
B13: 销售 | C13: =C5-C9 -> 2 | D13: =D5-D9 -> 32000 | E13: =E5-E9 -> 0 | F13: =F5-F9 -> 0 | G13: =G5-G9 -> 0 | H13: =H5-H9 -> 0 | I13: =I5-I9 -> -28137.93 | J13: =J5-J9 -> 0 | ... AC13: =AC5-AC9 -> 40060.58
B14: 合计 | C14: =SUM(C11:C13) -> 2 | D14: =SUM(D11:D13) -> 51000 | E14: =SUM(E11:E13) -> 0 | F14: =SUM(F11:F13) -> 0 | G14: =SUM(G11:G13) -> 0 | H14: =SUM(H11:H13) -> 0 | I14: =SUM(I11:I13) -> -131436.79 | J14: =SUM(J11:J13) -> 0 | ... AC14: =SUM(AC11:AC13) -> 109766.51
B17: 检查 | C17: =C6-工资表明细!L83 -> 0 | D17: =D6-工资表明细!P83 -> 0 | E17: =E6-工资表明细!Q83 -> 0 | F17: =F6-工资表明细!R83 -> 0 | G17: =G6-工资表明细!S83 -> 0 | H17: =H6-工资表明细!T83 -> 0 | I17: =I6-工资表明细!U83 -> 0 | J17: =J6-工资表明细!V83 -> 0 | K17: =K6-工资表明细!W83 -> 0 | ... Y17: =Y6-工资表明细!AK83 -> 0 | Z17: =Z6-工资表明细!AL83-工资表明细!AM83-工资表明细!AN83 -> -1.6370905e-11 | AA17: =AA6-工资表明细!AO83 -> 0 | AB17: =AB6-工资表明细!BE83 -> 0 | AC17: =AC6-工资表明细!BF83 -> 0

Sheet 同比变动
A1: 2025年8月创想悦动工资同比变动情况
A2: 年月 | B2: 项目 | C2: 人数 | D2: 基础工资 | E2: 绩效工资 | F2: 岗位津贴 | G2: 节日福利 | H2: 通讯补贴 | I2: 考勤扣款 | J2: 其他扣款 | K2: 加班费 | L2: 绩效奖金 | M2: 其他奖金 | N2: 伙食补贴 | O2: 住房补贴 | P2: 司机补贴 | Q2: 专利奖 | R2: 其他补发 | S2: 补发合计 | T2: 应付工资 | U2: 借款逾期扣款 | V2: 水电费 | W2: 房租 | X2: 其他代扣款 | Y2: 扣款合计 | Z2: 社保费 | AA2: 住房公积金 | AB2: 个人所得税 | AC2: 实发工资
A3: 46023 | B3: 职能 | C3: =环比变动!C3 -> 9 | D3: =环比变动!D3 -> 281000 | E3: =环比变动!E3 -> 0 | F3: =环比变动!F3 -> 0 | G3: =环比变动!G3 -> 0 | H3: =环比变动!H3 -> 0 | I3: =环比变动!I3 -> 0 | J3: =环比变动!J3 -> 0 | ... AC3: =环比变动!AC3 -> 206836.83
B4: 研发 | C4: =环比变动!C4 -> 55 | D4: =环比变动!D4 -> 1263300 | E4: =环比变动!E4 -> 0 | F4: =环比变动!F4 -> 0 | G4: =环比变动!G4 -> 0 | H4: =环比变动!H4 -> 0 | I4: =环比变动!I4 -> 43287.36 | J4: =环比变动!J4 -> 0 | ... AC4: =环比变动!AC4 -> 932559.11
B5: 销售 | C5: =环比变动!C5 -> 14 | D5: =环比变动!D5 -> 246000 | E5: =环比变动!E5 -> 0 | F5: =环比变动!F5 -> 0 | G5: =环比变动!G5 -> 0 | H5: =环比变动!H5 -> 0 | I5: =环比变动!I5 -> 6206.9 | J5: =环比变动!J5 -> 0 | ... AC5: =环比变动!AC5 -> 190569.54
B6: 合计 | C6: =SUM(C3:C5) -> 78 | D6: =SUM(D3:D5) -> 1790300 | E6: =SUM(E3:E5) -> 0 | F6: =SUM(F3:F5) -> 0 | G6: =SUM(G3:G5) -> 0 | H6: =SUM(H3:H5) -> 0 | I6: =SUM(I3:I5) -> 49494.26 | J6: =SUM(J3:J5) -> 0 | ... AC6: =SUM(AC3:AC5) -> 1329965.5
A7: 45658 | B7: 职能 | C7: 0 | D7: 0 | E7: 0 | F7: 0 | G7: 0 | H7: 0 | I7: 0 | J7: 0 | K7: 0 | L7: 0 | M7: 0 | N7: 0 | O7: 0 | P7: 0 | Q7: 0 | R7: 0 | S7: 0 | T7: 0
B8: 研发 | C8: 0 | D8: 0 | E8: 0 | F8: 0 | G8: 0 | H8: 0 | I8: 0 | J8: 0 | K8: 0 | L8: 0 | M8: 0 | N8: 0 | O8: 0 | P8: 0 | Q8: 0 | R8: 0 | S8: 0 | T8: 0
B9: 销售 | C9: 0 | D9: 0 | E9: 0 | F9: 0 | G9: 0 | H9: 0 | I9: 0 | J9: 0 | K9: 0 | L9: 0 | M9: 0 | N9: 0 | O9: 0 | P9: 0 | Q9: 0 | R9: 0 | S9: 0 | T9: 0
B10: 合计 | C10: =SUM(C7:C9) -> 0 | D10: =SUM(D7:D9) -> 0 | E10: =SUM(E7:E9) -> 0 | F10: =SUM(F7:F9) -> 0 | G10: =SUM(G7:G9) -> 0 | H10: =SUM(H7:H9) -> 0 | I10: =SUM(I7:I9) -> 0 | J10: =SUM(J7:J9) -> 0 | ... AC10: =SUM(AC7:AC9) -> 0
A11: 变动 | B11: 职能 | C11: =C3-C7 -> 9 | D11: =D3-D7 -> 281000 | E11: =E3-E7 -> 0 | F11: =F3-F7 -> 0 | G11: =G3-G7 -> 0 | H11: =H3-H7 -> 0 | I11: =I3-I7 -> 0 | J11: =J3-J7 -> 0 | ... AC11: =AC3-AC7 -> 206836.83
B12: 研发 | C12: =C4-C8 -> 55 | D12: =D4-D8 -> 1263300 | E12: =E4-E8 -> 0 | F12: =F4-F8 -> 0 | G12: =G4-G8 -> 0 | H12: =H4-H8 -> 0 | I12: =I4-I8 -> 43287.36 | J12: =J4-J8 -> 0 | ... AC12: =AC4-AC8 -> 932559.11
B13: 销售 | C13: =C5-C9 -> 14 | D13: =D5-D9 -> 246000 | E13: =E5-E9 -> 0 | F13: =F5-F9 -> 0 | G13: =G5-G9 -> 0 | H13: =H5-H9 -> 0 | I13: =I5-I9 -> 6206.9 | J13: =J5-J9 -> 0 | ... AC13: =AC5-AC9 -> 190569.54
B14: 合计 | C14: =SUM(C11:C13) -> 78 | D14: =SUM(D11:D13) -> 1790300 | E14: =SUM(E11:E13) -> 0 | F14: =SUM(F11:F13) -> 0 | G14: =SUM(G11:G13) -> 0 | H14: =SUM(H11:H13) -> 0 | I14: =SUM(I11:I13) -> 49494.26 | J14: =SUM(J11:J13) -> 0 | ... AC14: =SUM(AC11:AC13) -> 1329965.5

Sheet 各公司汇总
A1: 深圳创想悦动科技有限公司2026年7月工资表
A2: 一级成本中心 | B2: 成本中心编码 | C2: 人数 | D2: 基本工资 | E2: 绩效工资 | F2: 岗位津贴 | G2: 过节费 | H2: 通讯补贴 | I2: 考勤扣款 | J2: 其他扣款 | K2: 加班费 | L2: 绩效奖金 | M2: 其他奖金 | N2: 伙食补贴 | O2: 住房补贴 | P2: 司机补贴 | Q2: 专利奖 | R2: 其他补发 | S2: 补发合计 | T2: 应付工资 | U2: 借款逾期扣款 | V2: 房租水电 | W2: 房租水电1 | X2: 其他税后扣款 | Y2: 扣款合计 | Z2: 养老保险 | AA2: 医疗保险 | AB2: 失业保险 | AC2: 住房公积金 | AD2: 所得税 | AE2: 实发工资
A3: 创想悦动-管理 | B3: 创想悦动-管理 | C3: =SUMIF(工资表明细!$M$3:$M$85,$B3,工资表明细!$L$3:$L$85) -> 9 | D3: =SUMIF(工资表明细!$M$3:$M$82,$B3,工资表明细!P$3:P$82) -> 281000 | E3: =SUMIF(工资表明细!$M$3:$M$82,$B3,工资表明细!Q$3:Q$82) -> 0 | F3: =SUMIF(工资表明细!$M$3:$M$82,$B3,工资表明细!R$3:R$82) -> 0 | G3: =SUMIF(工资表明细!$M$3:$M$82,$B3,工资表明细!S$3:S$82) -> 0 | H3: =SUMIF(工资表明细!$M$3:$M$82,$B3,工资表明细!T$3:T$82) -> 0 | I3: =SUMIF(工资表明细!$M$3:$M$82,$B3,工资表明细!U$3:U$82) -> 0 | J3: =SUMIF(工资表明细!$M$3:$M$82,$B3,工资表明细!V$3:V$82) -> 0 | K3: =SUMIF(工资表明细!$M$3:$M$82,$B3,工资表明细!W$3:W$82) -> 0 | ... AC3: =SUMIF(工资表明细!$M$3:$M$82,$B3,工资表明细!AO$3:AO$82) -> 21739.5 | AD3: =SUMIF(工资表明细!$M$3:$M$82,$B3,工资表明细!BE$3:BE$82) -> 34577.71 | AE3: =SUMIF(工资表明细!$M$3:$M$82,$B3,工资表明细!BF$3:BF$82) -> 206836.83
A4: 创想悦动-研发 | B4: 创想悦动-研发 | C4: =SUMIF(工资表明细!$M$3:$M$85,$B4,工资表明细!$L$3:$L$85) -> 55 | D4: =SUMIF(工资表明细!$M$3:$M$82,$B4,工资表明细!P$3:P$82) -> 1263300 | E4: =SUMIF(工资表明细!$M$3:$M$82,$B4,工资表明细!Q$3:Q$82) -> 0 | F4: =SUMIF(工资表明细!$M$3:$M$82,$B4,工资表明细!R$3:R$82) -> 0 | G4: =SUMIF(工资表明细!$M$3:$M$82,$B4,工资表明细!S$3:S$82) -> 0 | H4: =SUMIF(工资表明细!$M$3:$M$82,$B4,工资表明细!T$3:T$82) -> 0 | I4: =SUMIF(工资表明细!$M$3:$M$82,$B4,工资表明细!U$3:U$82) -> 43287.36 | J4: =SUMIF(工资表明细!$M$3:$M$82,$B4,工资表明细!V$3:V$82) -> 0 | K4: =SUMIF(工资表明细!$M$3:$M$82,$B4,工资表明细!W$3:W$82) -> 0 | ... AC4: =SUMIF(工资表明细!$M$3:$M$82,$B4,工资表明细!AO$3:AO$82) -> 88863.6 | AD4: =SUMIF(工资表明细!$M$3:$M$82,$B4,工资表明细!BE$3:BE$82) -> 85237.98 | AE4: =SUMIF(工资表明细!$M$3:$M$82,$B4,工资表明细!BF$3:BF$82) -> 932559.11
A5: 创想悦动-销售 | B5: 创想悦动-销售 | C5: =SUMIF(工资表明细!$M$3:$M$85,$B5,工资表明细!$L$3:$L$85) -> 14 | D5: =SUMIF(工资表明细!$M$3:$M$82,$B5,工资表明细!P$3:P$82) -> 246000 | E5: =SUMIF(工资表明细!$M$3:$M$82,$B5,工资表明细!Q$3:Q$82) -> 0 | F5: =SUMIF(工资表明细!$M$3:$M$82,$B5,工资表明细!R$3:R$82) -> 0 | G5: =SUMIF(工资表明细!$M$3:$M$82,$B5,工资表明细!S$3:S$82) -> 0 | H5: =SUMIF(工资表明细!$M$3:$M$82,$B5,工资表明细!T$3:T$82) -> 0 | I5: =SUMIF(工资表明细!$M$3:$M$82,$B5,工资表明细!U$3:U$82) -> 6206.9 | J5: =SUMIF(工资表明细!$M$3:$M$82,$B5,工资表明细!V$3:V$82) -> 0 | K5: =SUMIF(工资表明细!$M$3:$M$82,$B5,工资表明细!W$3:W$82) -> 0 | ... AC5: =SUMIF(工资表明细!$M$3:$M$82,$B5,工资表明细!AO$3:AO$82) -> 20480 | AD5: =SUMIF(工资表明细!$M$3:$M$82,$B5,工资表明细!BE$3:BE$82) -> 7179.72 | AE5: =SUMIF(工资表明细!$M$3:$M$82,$B5,工资表明细!BF$3:BF$82) -> 190569.54
A6: 总计 | C6: =SUM(C3:C5) -> 78 | D6: =SUM(D3:D5) -> 1790300 | E6: =SUM(E3:E5) -> 0 | F6: =SUM(F3:F5) -> 0 | G6: =SUM(G3:G5) -> 0 | H6: =SUM(H3:H5) -> 0 | I6: =SUM(I3:I5) -> 49494.26 | J6: =SUM(J3:J5) -> 0 | ... AE6: =SUM(AE3:AE5) -> 1329965.5
A8: 制表： | E8: 财务部： | K8: 人力资源部总监审批： | T8: 财务部总监审批： | Z8: 审批： | AC8: 审批：
A18: 深圳创想悦动科技有限公司2026年7月工资表
A19: 二级部门 | B19: 二级部门 | C19: 人数 | D19: 基本工资 | E19: 绩效工资 | F19: 岗位津贴 | G19: 过节费 | H19: 通讯补贴 | I19: 考勤扣款 | J19: 其他扣款 | K19: 加班费 | L19: 绩效奖金 | M19: 其他奖金 | N19: 伙食补贴 | O19: 住房补贴 | P19: 司机补贴 | Q19: 专利奖 | R19: 其他补发 | S19: 补发合计 | T19: 应付工资 | U19: 借款逾期扣款 | V19: 房租水电 | W19: 房租水电1 | X19: 其他税后扣款 | Y19: 扣款合计 | Z19: 养老保险 | AA19: 医疗保险 | AB19: 失业保险 | AC19: 住房公积金 | AD19: 所得税 | AE19: 实发工资
A20: 公共设计组 | B20: 公共设计组 | C20: =SUMIF(工资表明细!$G$3:$G$82,$B20,工资表明细!$L$3:$L$82) -> 4 | D20: =SUMIF(工资表明细!$G$3:$G$82,$B20,工资表明细!P$3:P$82) -> 80000 | E20: =SUMIF(工资表明细!$G$3:$G$82,$B20,工资表明细!Q$3:Q$82) -> 0 | F20: =SUMIF(工资表明细!$G$3:$G$82,$B20,工资表明细!R$3:R$82) -> 0 | G20: =SUMIF(工资表明细!$G$3:$G$82,$B20,工资表明细!S$3:S$82) -> 0 | H20: =SUMIF(工资表明细!$G$3:$G$82,$B20,工资表明细!T$3:T$82) -> 0 | I20: =SUMIF(工资表明细!$G$3:$G$82,$B20,工资表明细!U$3:U$82) -> 0 | J20: =SUMIF(工资表明细!$G$3:$G$82,$B20,工资表明细!V$3:V$82) -> 0 | K20: =SUMIF(工资表明细!$G$3:$G$82,$B20,工资表明细!W$3:W$82) -> 0 | ... Z20: =SUMIF(工资表明细!$G$3:$G$82,$B20,工资表明细!AL$3:AL$82) -> 6400 | AA20: =SUMIF(工资表明细!$G$3:$G$82,$B20,工资表明细!AG$3:AG$82) -> 0 | AB20: =SUMIF(工资表明细!$G$3:$G$82,$B20,工资表明细!AN$3:AN$82) -> 160 | AC20: =SUMIF(工资表明细!$G$3:$G$82,$B20,工资表明细!AO$3:AO$82) -> 4620 | AD20: =SUMIF(工资表明细!$G$3:$G$82,$B20,工资表明细!BE$3:BE$82) -> 3072.9 | AE20: =SUMIF(工资表明细!$G$3:$G$82,$B20,工资表明细!BF$3:BF$82) -> 64547.1
A21: 品牌宣传组 | B21: 品牌宣传组 | C21: =SUMIF(工资表明细!$G$3:$G$82,$B21,工资表明细!$L$3:$L$82) -> 3 | D21: =SUMIF(工资表明细!$G$3:$G$82,$B21,工资表明细!P$3:P$82) -> 78000 | E21: =SUMIF(工资表明细!$G$3:$G$82,$B21,工资表明细!Q$3:Q$82) -> 0 | F21: =SUMIF(工资表明细!$G$3:$G$82,$B21,工资表明细!R$3:R$82) -> 0 | G21: =SUMIF(工资表明细!$G$3:$G$82,$B21,工资表明细!S$3:S$82) -> 0 | H21: =SUMIF(工资表明细!$G$3:$G$82,$B21,工资表明细!T$3:T$82) -> 0 | I21: =SUMIF(工资表明细!$G$3:$G$82,$B21,工资表明细!U$3:U$82) -> 2206.9 | J21: =SUMIF(工资表明细!$G$3:$G$82,$B21,工资表明细!V$3:V$82) -> 0 | K21: =SUMIF(工资表明细!$G$3:$G$82,$B21,工资表明细!W$3:W$82) -> 0 | ... Z21: =SUMIF(工资表明细!$G$3:$G$82,$B21,工资表明细!AL$3:AL$82) -> 5643.92 | AA21: =SUMIF(工资表明细!$G$3:$G$82,$B21,工资表明细!AG$3:AG$82) -> 0 | AB21: =SUMIF(工资表明细!$G$3:$G$82,$B21,工资表明细!AN$3:AN$82) -> 156 | AC21: =SUMIF(工资表明细!$G$3:$G$82,$B21,工资表明细!AO$3:AO$82) -> 5160 | AD21: =SUMIF(工资表明细!$G$3:$G$82,$B21,工资表明细!BE$3:BE$82) -> 3195.75 | AE21: =SUMIF(工资表明细!$G$3:$G$82,$B21,工资表明细!BF$3:BF$82) -> 60664.77
A22: 游戏研发部 | B22: 游戏研发部 | C22: =SUMIF(工资表明细!$G$3:$G$82,$B22,工资表明细!$L$3:$L$82) -> 33 | D22: =SUMIF(工资表明细!$G$3:$G$82,$B22,工资表明细!P$3:P$82) -> 770300 | E22: =SUMIF(工资表明细!$G$3:$G$82,$B22,工资表明细!Q$3:Q$82) -> 0 | F22: =SUMIF(工资表明细!$G$3:$G$82,$B22,工资表明细!R$3:R$82) -> 0 | G22: =SUMIF(工资表明细!$G$3:$G$82,$B22,工资表明细!S$3:S$82) -> 0 | H22: =SUMIF(工资表明细!$G$3:$G$82,$B22,工资表明细!T$3:T$82) -> 0 | I22: =SUMIF(工资表明细!$G$3:$G$82,$B22,工资表明细!U$3:U$82) -> 14298.85 | J22: =SUMIF(工资表明细!$G$3:$G$82,$B22,工资表明细!V$3:V$82) -> 0 | K22: =SUMIF(工资表明细!$G$3:$G$82,$B22,工资表明细!W$3:W$82) -> 0 | ... Z22: =SUMIF(工资表明细!$G$3:$G$82,$B22,工资表明细!AL$3:AL$82) -> 53951.36 | AA22: =SUMIF(工资表明细!$G$3:$G$82,$B22,工资表明细!AG$3:AG$82) -> 0 | AB22: =SUMIF(工资表明细!$G$3:$G$82,$B22,工资表明细!AN$3:AN$82) -> 1529.54 | AC22: =SUMIF(工资表明细!$G$3:$G$82,$B22,工资表明细!AO$3:AO$82) -> 56103.6 | AD22: =SUMIF(工资表明细!$G$3:$G$82,$B22,工资表明细!BE$3:BE$82) -> 54397.54 | AE22: =SUMIF(工资表明细!$G$3:$G$82,$B22,工资表明细!BF$3:BF$82) -> 573282.9
A23: 商务合作部 | B23: 商务合作部 | C23: =SUMIF(工资表明细!$G$3:$G$82,$B23,工资表明细!$L$3:$L$82) -> 6 | D23: =SUMIF(工资表明细!$G$3:$G$82,$B23,工资表明细!P$3:P$82) -> 117000 | E23: =SUMIF(工资表明细!$G$3:$G$82,$B23,工资表明细!Q$3:Q$82) -> 0 | F23: =SUMIF(工资表明细!$G$3:$G$82,$B23,工资表明细!R$3:R$82) -> 0 | G23: =SUMIF(工资表明细!$G$3:$G$82,$B23,工资表明细!S$3:S$82) -> 0 | H23: =SUMIF(工资表明细!$G$3:$G$82,$B23,工资表明细!T$3:T$82) -> 0 | I23: =SUMIF(工资表明细!$G$3:$G$82,$B23,工资表明细!U$3:U$82) -> 183.91 | J23: =SUMIF(工资表明细!$G$3:$G$82,$B23,工资表明细!V$3:V$82) -> 0 | K23: =SUMIF(工资表明细!$G$3:$G$82,$B23,工资表明细!W$3:W$82) -> 0 | ... Z23: =SUMIF(工资表明细!$G$3:$G$82,$B23,工资表明细!AL$3:AL$82) -> 5323.92 | AA23: =SUMIF(工资表明细!$G$3:$G$82,$B23,工资表明细!AG$3:AG$82) -> 0 | AB23: =SUMIF(工资表明细!$G$3:$G$82,$B23,工资表明细!AN$3:AN$82) -> 150 | AC23: =SUMIF(工资表明细!$G$3:$G$82,$B23,工资表明细!AO$3:AO$82) -> 6500 | AD23: =SUMIF(工资表明细!$G$3:$G$82,$B23,工资表明细!BE$3:BE$82) -> 9377.56 | AE23: =SUMIF(工资表明细!$G$3:$G$82,$B23,工资表明细!BF$3:BF$82) -> 94924.61
A24: 基础产品部 | B24: 基础产品部 | C24: =SUMIF(工资表明细!$G$3:$G$82,$B24,工资表明细!$L$3:$L$82) -> 17 | D24: =SUMIF(工资表明细!$G$3:$G$82,$B24,工资表明细!P$3:P$82) -> 467000 | E24: =SUMIF(工资表明细!$G$3:$G$82,$B24,工资表明细!Q$3:Q$82) -> 0 | F24: =SUMIF(工资表明细!$G$3:$G$82,$B24,工资表明细!R$3:R$82) -> 0 | G24: =SUMIF(工资表明细!$G$3:$G$82,$B24,工资表明细!S$3:S$82) -> 0 | H24: =SUMIF(工资表明细!$G$3:$G$82,$B24,工资表明细!T$3:T$82) -> 0 | I24: =SUMIF(工资表明细!$G$3:$G$82,$B24,工资表明细!U$3:U$82) -> 28988.51 | J24: =SUMIF(工资表明细!$G$3:$G$82,$B24,工资表明细!V$3:V$82) -> 0 | K24: =SUMIF(工资表明细!$G$3:$G$82,$B24,工资表明细!W$3:W$82) -> 0 | ... Z24: =SUMIF(工资表明细!$G$3:$G$82,$B24,工资表明细!AL$3:AL$82) -> 26947.44 | AA24: =SUMIF(工资表明细!$G$3:$G$82,$B24,工资表明细!AG$3:AG$82) -> 0 | AB24: =SUMIF(工资表明细!$G$3:$G$82,$B24,工资表明细!AN$3:AN$82) -> 827.88 | AC24: =SUMIF(工资表明细!$G$3:$G$82,$B24,工资表明细!AO$3:AO$82) -> 35599.5 | AD24: =SUMIF(工资表明细!$G$3:$G$82,$B24,工资表明细!BE$3:BE$82) -> 44325.1 | AE24: =SUMIF(工资表明细!$G$3:$G$82,$B24,工资表明细!BF$3:BF$82) -> 324780.93
A25: 人资行政组 | B25: 人资行政组 | C25: =SUMIF(工资表明细!$G$3:$G$82,$B25,工资表明细!$L$3:$L$82) -> 4 | D25: =SUMIF(工资表明细!$G$3:$G$82,$B25,工资表明细!P$3:P$82) -> 60000 | E25: =SUMIF(工资表明细!$G$3:$G$82,$B25,工资表明细!Q$3:Q$82) -> 0 | F25: =SUMIF(工资表明细!$G$3:$G$82,$B25,工资表明细!R$3:R$82) -> 0 | G25: =SUMIF(工资表明细!$G$3:$G$82,$B25,工资表明细!S$3:S$82) -> 0 | H25: =SUMIF(工资表明细!$G$3:$G$82,$B25,工资表明细!T$3:T$82) -> 0 | I25: =SUMIF(工资表明细!$G$3:$G$82,$B25,工资表明细!U$3:U$82) -> 0 | J25: =SUMIF(工资表明细!$G$3:$G$82,$B25,工资表明细!V$3:V$82) -> 0 | K25: =SUMIF(工资表明细!$G$3:$G$82,$B25,工资表明细!W$3:W$82) -> 0 | ... Z25: =SUMIF(工资表明细!$G$3:$G$82,$B25,工资表明细!AL$3:AL$82) -> 4800 | AA25: =SUMIF(工资表明细!$G$3:$G$82,$B25,工资表明细!AG$3:AG$82) -> 0 | AB25: =SUMIF(工资表明细!$G$3:$G$82,$B25,工资表明细!AN$3:AN$82) -> 120 | AC25: =SUMIF(工资表明细!$G$3:$G$82,$B25,工资表明细!AO$3:AO$82) -> 6360 | AD25: =SUMIF(工资表明细!$G$3:$G$82,$B25,工资表明细!BE$3:BE$82) -> 2102.96 | AE25: =SUMIF(工资表明细!$G$3:$G$82,$B25,工资表明细!BF$3:BF$82) -> 44437.28
A26: 平台运营部 | B26: 平台运营部 | C26: =SUMIF(工资表明细!$G$3:$G$82,$B26,工资表明细!$L$3:$L$82) -> 11 | D26: =SUMIF(工资表明细!$G$3:$G$82,$B26,工资表明细!P$3:P$82) -> 218000 | E26: =SUMIF(工资表明细!$G$3:$G$82,$B26,工资表明细!Q$3:Q$82) -> 0 | F26: =SUMIF(工资表明细!$G$3:$G$82,$B26,工资表明细!R$3:R$82) -> 0 | G26: =SUMIF(工资表明细!$G$3:$G$82,$B26,工资表明细!S$3:S$82) -> 0 | H26: =SUMIF(工资表明细!$G$3:$G$82,$B26,工资表明细!T$3:T$82) -> 0 | I26: =SUMIF(工资表明细!$G$3:$G$82,$B26,工资表明细!U$3:U$82) -> 3816.09 | J26: =SUMIF(工资表明细!$G$3:$G$82,$B26,工资表明细!V$3:V$82) -> 0 | K26: =SUMIF(工资表明细!$G$3:$G$82,$B26,工资表明细!W$3:W$82) -> 0 | ... Z26: =SUMIF(工资表明细!$G$3:$G$82,$B26,工资表明细!AL$3:AL$82) -> 16211.76 | AA26: =SUMIF(工资表明细!$G$3:$G$82,$B26,工资表明细!AG$3:AG$82) -> 0 | AB26: =SUMIF(工资表明细!$G$3:$G$82,$B26,工资表明细!AN$3:AN$82) -> 428 | AC26: =SUMIF(工资表明细!$G$3:$G$82,$B26,工资表明细!AO$3:AO$82) -> 16740 | AD26: =SUMIF(工资表明细!$G$3:$G$82,$B26,工资表明细!BE$3:BE$82) -> 10523.6 | AE26: =SUMIF(工资表明细!$G$3:$G$82,$B26,工资表明细!BF$3:BF$82) -> 167327.89
A27: 总计 | C27: =SUM(C20:C26) -> 78 | D27: =SUM(D20:D26) -> 1790300 | E27: =SUM(E20:E26) -> 0 | F27: =SUM(F20:F26) -> 0 | G27: =SUM(G20:G26) -> 0 | H27: =SUM(H20:H26) -> 0 | I27: =SUM(I20:I26) -> 49494.26 | J27: =SUM(J20:J26) -> 0 | ... AE27: =SUM(AE20:AE26) -> 1329965.5
A29: 制表： | E29: 财务部： | K29: 人力资源部总监审批： | T29: 财务部总监审批： | Z29: 审批： | AC29: 审批：

Sheet 工资表明细
A1: 深圳创想悦动科技有限公司2026年7月工资表
A2: 序号 | B2: 归属公司 | C2: 工号 | D2: 姓名 | E2: 用工类型 | F2: 一级部门 | G2: 二级部门 | H2: 报到本公司日期 | I2: 离职日期 | J2: 一级成本中心 | K2: 专业 | L2: 人数 | M2: 成本中心编码 | N2: 身份证号码 | O2: 卡号 | P2: 基本工资 | Q2: 绩效工资 | R2: 岗位津贴 | S2: 节日福利 | T2: 通讯补贴 | U2: 考勤扣款 | V2: 其他扣款 | W2: 加班费 | X2: 绩效奖金 | Y2: 其他奖金 | Z2: 伙食补贴 | AA2: 住房补贴 | AB2: 司机补贴 | AC2: 专利奖金 | AD2: 其他补发 | AE2: 补发合计 | AF2: 应付工资 | AG2: 借款逾期扣款 | AH2: 房租水电 | AI2: 房租水电1 | AJ2: 其他税后扣款 | AK2: 扣款合计 | AL2: 养老保险 | AM2: 医疗保险 | AN2: 失业保险 | AO2: 住房公积金 | AP2: 累计子女教育 | AQ2: 累计继续教育 | AR2: 累计住房贷款利息 | AS2: 累计住房租金 | AT2: 累计赡养老人 | AU2: 累计婴幼儿照护费用 | AV2: 累计个人养老金 | AW2: 免税额 | AX2: 本月合计扣除 | AY2: 截止上月累计收入 | AZ2: 截止本月累计收入 （实习扣减20%） | BA2: 截止上月累计扣除 | BB2: 截止当月累计扣除 | BC2: 截止本月应交个税 | BD2: 累计已扣税额 | BE2: 本月应交个税 | BF2: 实发工资 | BH2: 邮箱 | BI2: 总体逻辑检查 | BJ2: 备注
A3: =ROW()-2 -> 1 | B3: 创想悦动 | C3: SCX00001 | D3: 刘丹 | E3: 合同制人员 | F3: 创想悦动 | G3: 基础产品部 | H3: 45880 | J3: 创想悦动-管理 | K3: 计算机网络技术 | L3: 1 | M3: 创想悦动-管理 | N3: 420502197605290638 | O3: 6214855253515072 | P3: 50000 | Q3: =ROUND(SUMIF(其他补发!B:B,$C3,其他补发!D:D),2) -> 0 | R3: =ROUND(SUMIF(其他补发!B:B,$C3,其他补发!H:H),2) -> 0 | S3: =ROUND(SUMIF(其他补发!B:B,$C3,其他补发!I:I),2) -> 0 | T3: =ROUND(SUMIF(其他补发!B:B,$C3,其他补发!E:E),2) -> 0 | U3: =ROUND((VLOOKUP(C3,考勤!C:H,6,0)+VLOOKUP(C3,考勤!C:O,13,0)+VLOOKUP(C3,考勤!C:P,14,0)*0.3+VLOOKUP(C3,考勤!C:AA,25,0))*(P3+Q3+R3)/21.75,2)+ROUND((VLOOKUP(C3,考勤!C:V,19,0)+VLOOKUP(C3,考勤!C:V,20,0))*(P3+Q3+R3-2520)/21.75,2) -> 0 | V3: =ROUND(SUMIF(动态表!C:C,C3,动态表!AA:AA)+SUMIFS(其他补发!L:L,其他补发!B:B,C3),2) -> 0 | W3: =ROUND(VLOOKUP(C3,考勤!C:K,9,0)*P3/21.75/8*2+VLOOKUP(C3,考勤!C:L,10,0)*P3/21.75/8*3,2)+SUMIFS(加班费!$H:$H,加班费!$D:$D,$C3) -> 0 | X3: =SUMIF(奖金!D:D,C3,奖金!F:F) -> 0 | Y3: =SUMIF(其他补发!B:B,C3,其他补发!J:J) -> 0 | Z3: =SUMIF(其他补发!B:B,C3,其他补发!F:F) -> 0 | AA3: =SUMIF(其他补发!B:B,C3,其他补发!G:G) -> 0 | AB3: =SUMIF(其他补发!B:B,C3,其他补发!M:M) -> 0 | AC3: =SUMIF(其他补发!B:B,C3,其他补发!N:N) -> 0 | AD3: =SUMIF(其他补发!B:B,C3,其他补发!K:K) -> 0 | AE3: =AD3+AC3+AB3+AA3+Z3+Y3+X3+W3 -> 0 | AF3: =ROUND((P3+Q3+R3+S3+T3-U3-V3+AE3),2) -> 50000 | AG3: =SUMIF(税后扣款!B:B,C3,税后扣款!E:E) -> 0 | AH3: =SUMIF(房租水电!A:A,C3,房租水电!C:C) -> 0 | AI3: =SUMIF(房租水电!A:A,C3,房租水电!D:D) -> 0 | AJ3: =SUMIF(税后扣款!B:B,C3,税后扣款!D:D) -> -240 | AK3: =AJ3+AI3+AH3+AG3 -> -240 | AL3: =SUMIF(社会保险!D:D,N3,社会保险!I:I) -> 2203.92 | AM3: =SUMIF(社会保险!D:D,N3,社会保险!J:J) -> 672.66 | AN3: =SUMIF(社会保险!D:D,N3,社会保险!K:K) -> 96.94 | AO3: =SUMIF(公积金!C:C,N3,公积金!L:L) -> 5311.8 | AP3: =SUMIF(专项扣除!$B:$B,$C3,专项扣除!D:D) -> 0 | AQ3: =SUMIF(专项扣除!$B:$B,$C3,专项扣除!E:E) -> 0 | AR3: =SUMIF(专项扣除!$B:$B,$C3,专项扣除!F:F) -> 0 | AS3: =SUMIF(专项扣除!$B:$B,$C3,专项扣除!G:G) -> 0 | AT3: =SUMIF(专项扣除!$B:$B,$C3,专项扣除!H:H) -> 0 | AU3: =SUMIF(专项扣除!$B:$B,$C3,专项扣除!I:I) -> 0 | AV3: =SUMIF(专项扣除!$B:$B,$C3,专项扣除!J:J) -> 0 | AW3: 5000 | AX3: =AL3+AM3+AN3+AO3+AW3 -> 13285.32 | AY3: =SUMIF(上月累计工资累计社保和公积金!C:C,C3,上月累计工资累计社保和公积金!E:E) -> 350500 | AZ3: =IF(E3="实习人员",(AY3+AF3)*80%,AY3+AF3) -> 400500 | BA3: =SUMIF(上月累计工资累计社保和公积金!C:C,C3,上月累计工资累计社保和公积金!K:K) -> 74347.73 | BB3: =BA3+AX3 -> 87633.05 | BC3: =ROUND(MAX((AZ3-BB3-AP3-AQ3-AR3-AS3-AT3-AU3-AV3)*0.01*{3,10,20,25,30,35,45}-{0,2520,16920,31920,52920,85920,181920},0),2) -> 46296.74 | BD3: =SUMIF(上月累计工资累计社保和公积金!C:C,C3,上月累计工资累计社保和公积金!L:L) -> 38310.45 | BE3: =IF((BC3-BD3)<0,0,((BC3-BD3))) -> 7986.29 | BF3: =ROUND((AF3-AK3-BE3-AL3-AM3-AN3-AO3),2) -> 33968.39 | BH3: =VLOOKUP(C3,考勤!C:AL,36,0) -> liudan@youdoogo.com | BI3: =P3+Q3+R3+S3+T3-U3-V3+W3+X3+Y3+Z3+AA3+AB3+AC3+AD3-AG3-AH3-AI3-AJ3-AL3-AM3-AN3-AO3-BE3-BF3 -> 0
A4: =ROW()-2 -> 2 | B4: 创想悦动 | C4: SCX00002 | D4: 李奕佳 | E4: 合同制人员 | F4: 创想悦动 | G4: 人资行政组 | H4: 45880 | J4: 创想悦动-管理 | K4: 生物化学与分子生物学 | L4: 1 | M4: 创想悦动-管理 | N4: 330302200101050448 | O4: 6214834366472596 | P4: 16000 | Q4: =ROUND(SUMIF(其他补发!B:B,$C4,其他补发!D:D),2) -> 0 | R4: =ROUND(SUMIF(其他补发!B:B,$C4,其他补发!H:H),2) -> 0 | S4: =ROUND(SUMIF(其他补发!B:B,$C4,其他补发!I:I),2) -> 0 | T4: =ROUND(SUMIF(其他补发!B:B,$C4,其他补发!E:E),2) -> 0 | U4: =ROUND((VLOOKUP(C4,考勤!C:H,6,0)+VLOOKUP(C4,考勤!C:O,13,0)+VLOOKUP(C4,考勤!C:P,14,0)*0.3+VLOOKUP(C4,考勤!C:AA,25,0))*(P4+Q4+R4)/21.75,2)+ROUND((VLOOKUP(C4,考勤!C:V,19,0)+VLOOKUP(C4,考勤!C:V,20,0))*(P4+Q4+R4-2520)/21.75,2) -> 0 | V4: =ROUND(SUMIF(动态表!C:C,C4,动态表!AA:AA)+SUMIFS(其他补发!L:L,其他补发!B:B,C4),2) -> 0 | W4: =ROUND(VLOOKUP(C4,考勤!C:K,9,0)*P4/21.75/8*2+VLOOKUP(C4,考勤!C:L,10,0)*P4/21.75/8*3,2)+SUMIFS(加班费!$H:$H,加班费!$D:$D,$C4) -> 0 | X4: =SUMIF(奖金!D:D,C4,奖金!F:F) -> 0 | Y4: =SUMIF(其他补发!B:B,C4,其他补发!J:J) -> 0 | Z4: =SUMIF(其他补发!B:B,C4,其他补发!F:F) -> 0 | AA4: =SUMIF(其他补发!B:B,C4,其他补发!G:G) -> 0 | AB4: =SUMIF(其他补发!B:B,C4,其他补发!M:M) -> 0 | AC4: =SUMIF(其他补发!B:B,C4,其他补发!N:N) -> 0 | AD4: =SUMIF(其他补发!B:B,C4,其他补发!K:K) -> 0 | AE4: =AD4+AC4+AB4+AA4+Z4+Y4+X4+W4 -> 0 | AF4: =ROUND((P4+Q4+R4+S4+T4-U4-V4+AE4),2) -> 16000 | AG4: =SUMIF(税后扣款!B:B,C4,税后扣款!E:E) -> 0 | AH4: =SUMIF(房租水电!A:A,C4,房租水电!C:C) -> 0 | AI4: =SUMIF(房租水电!A:A,C4,房租水电!D:D) -> 0 | AJ4: =SUMIF(税后扣款!B:B,C4,税后扣款!D:D) -> -240 | AK4: =AJ4+AI4+AH4+AG4 -> -240 | AL4: =SUMIF(社会保险!D:D,N4,社会保险!I:I) -> 1280 | AM4: =SUMIF(社会保险!D:D,N4,社会保险!J:J) -> 320 | AN4: =SUMIF(社会保险!D:D,N4,社会保险!K:K) -> 32 | AO4: =SUMIF(公积金!C:C,N4,公积金!L:L) -> 1680 | AP4: =SUMIF(专项扣除!$B:$B,$C4,专项扣除!D:D) -> 0 | AQ4: =SUMIF(专项扣除!$B:$B,$C4,专项扣除!E:E) -> 0 | AR4: =SUMIF(专项扣除!$B:$B,$C4,专项扣除!F:F) -> 0 | AS4: =SUMIF(专项扣除!$B:$B,$C4,专项扣除!G:G) -> 10500 | AT4: =SUMIF(专项扣除!$B:$B,$C4,专项扣除!H:H) -> 0 | AU4: =SUMIF(专项扣除!$B:$B,$C4,专项扣除!I:I) -> 0 | AV4: =SUMIF(专项扣除!$B:$B,$C4,专项扣除!J:J) -> 0 | AW4: 5000 | AX4: =AL4+AM4+AN4+AO4+AW4 -> 8312 | AY4: =SUMIF(上月累计工资累计社保和公积金!C:C,C4,上月累计工资累计社保和公积金!E:E) -> 104300 | AZ4: =IF(E4="实习人员",(AY4+AF4)*80%,AY4+AF4) -> 120300 | BA4: =SUMIF(上月累计工资累计社保和公积金!C:C,C4,上月累计工资累计社保和公积金!K:K) -> 51488 | BB4: =BA4+AX4 -> 59800 | BC4: =ROUND(MAX((AZ4-BB4-AP4-AQ4-AR4-AS4-AT4-AU4-AV4)*0.01*{3,10,20,25,30,35,45}-{0,2520,16920,31920,52920,85920,181920},0),2) -> 2480 | BD4: =SUMIF(上月累计工资累计社保和公积金!C:C,C4,上月累计工资累计社保和公积金!L:L) -> 1711.2 | BE4: =IF((BC4-BD4)<0,0,((BC4-BD4))) -> 768.8 | BF4: =ROUND((AF4-AK4-BE4-AL4-AM4-AN4-AO4),2) -> 12159.2 | BH4: =VLOOKUP(C4,考勤!C:AL,36,0) -> liyijia@youdoogo.com | BI4: =P4+Q4+R4+S4+T4-U4-V4+W4+X4+Y4+Z4+AA4+AB4+AC4+AD4-AG4-AH4-AI4-AJ4-AL4-AM4-AN4-AO4-BE4-BF4 -> 0
A5: =ROW()-2 -> 3 | B5: 创想悦动 | C5: SCX00003 | D5: 申华 | E5: 合同制人员 | F5: 创想悦动 | G5: 基础产品部 | H5: 45880 | J5: 创想悦动-管理 | K5: 计算机科学与技术 | L5: 1 | M5: 创想悦动-管理 | N5: 610121198412260077 | O5: 6226096554090061 | P5: 50000 | Q5: =ROUND(SUMIF(其他补发!B:B,$C5,其他补发!D:D),2) -> 0 | R5: =ROUND(SUMIF(其他补发!B:B,$C5,其他补发!H:H),2) -> 0 | S5: =ROUND(SUMIF(其他补发!B:B,$C5,其他补发!I:I),2) -> 0 | T5: =ROUND(SUMIF(其他补发!B:B,$C5,其他补发!E:E),2) -> 0 | U5: =ROUND((VLOOKUP(C5,考勤!C:H,6,0)+VLOOKUP(C5,考勤!C:O,13,0)+VLOOKUP(C5,考勤!C:P,14,0)*0.3+VLOOKUP(C5,考勤!C:AA,25,0))*(P5+Q5+R5)/21.75,2)+ROUND((VLOOKUP(C5,考勤!C:V,19,0)+VLOOKUP(C5,考勤!C:V,20,0))*(P5+Q5+R5-2520)/21.75,2) -> 0 | V5: =ROUND(SUMIF(动态表!C:C,C5,动态表!AA:AA)+SUMIFS(其他补发!L:L,其他补发!B:B,C5),2) -> 0 | W5: =ROUND(VLOOKUP(C5,考勤!C:K,9,0)*P5/21.75/8*2+VLOOKUP(C5,考勤!C:L,10,0)*P5/21.75/8*3,2)+SUMIFS(加班费!$H:$H,加班费!$D:$D,$C5) -> 0 | X5: =SUMIF(奖金!D:D,C5,奖金!F:F) -> 0 | Y5: =SUMIF(其他补发!B:B,C5,其他补发!J:J) -> 0 | Z5: =SUMIF(其他补发!B:B,C5,其他补发!F:F) -> 0 | AA5: =SUMIF(其他补发!B:B,C5,其他补发!G:G) -> 0 | AB5: =SUMIF(其他补发!B:B,C5,其他补发!M:M) -> 0 | AC5: =SUMIF(其他补发!B:B,C5,其他补发!N:N) -> 0 | AD5: =SUMIF(其他补发!B:B,C5,其他补发!K:K) -> 0 | AE5: =AD5+AC5+AB5+AA5+Z5+Y5+X5+W5 -> 0 | AF5: =ROUND((P5+Q5+R5+S5+T5-U5-V5+AE5),2) -> 50000 | AG5: =SUMIF(税后扣款!B:B,C5,税后扣款!E:E) -> 0 | AH5: =SUMIF(房租水电!A:A,C5,房租水电!C:C) -> 0 | AI5: =SUMIF(房租水电!A:A,C5,房租水电!D:D) -> 0 | AJ5: =SUMIF(税后扣款!B:B,C5,税后扣款!D:D) -> -240 | AK5: =AJ5+AI5+AH5+AG5 -> -240 | AL5: =SUMIF(社会保险!D:D,N5,社会保险!I:I) -> 2203.92 | AM5: =SUMIF(社会保险!D:D,N5,社会保险!J:J) -> 672.66 | AN5: =SUMIF(社会保险!D:D,N5,社会保险!K:K) -> 96.94 | AO5: =SUMIF(公积金!C:C,N5,公积金!L:L) -> 5311.8 | AP5: =SUMIF(专项扣除!$B:$B,$C5,专项扣除!D:D) -> 0 | AQ5: =SUMIF(专项扣除!$B:$B,$C5,专项扣除!E:E) -> 0 | AR5: =SUMIF(专项扣除!$B:$B,$C5,专项扣除!F:F) -> 0 | AS5: =SUMIF(专项扣除!$B:$B,$C5,专项扣除!G:G) -> 0 | AT5: =SUMIF(专项扣除!$B:$B,$C5,专项扣除!H:H) -> 0 | AU5: =SUMIF(专项扣除!$B:$B,$C5,专项扣除!I:I) -> 0 | AV5: =SUMIF(专项扣除!$B:$B,$C5,专项扣除!J:J) -> 0 | AW5: 5000 | AX5: =AL5+AM5+AN5+AO5+AW5 -> 13285.32 | AY5: =SUMIF(上月累计工资累计社保和公积金!C:C,C5,上月累计工资累计社保和公积金!E:E) -> 349150.57 | AZ5: =IF(E5="实习人员",(AY5+AF5)*80%,AY5+AF5) -> 399150.57 | BA5: =SUMIF(上月累计工资累计社保和公积金!C:C,C5,上月累计工资累计社保和公积金!K:K) -> 74347.73 | BB5: =BA5+AX5 -> 87633.05 | BC5: =ROUND(MAX((AZ5-BB5-AP5-AQ5-AR5-AS5-AT5-AU5-AV5)*0.01*{3,10,20,25,30,35,45}-{0,2520,16920,31920,52920,85920,181920},0),2) -> 45959.38 | BD5: =SUMIF(上月累计工资累计社保和公积金!C:C,C5,上月累计工资累计社保和公积金!L:L) -> 38040.57 | BE5: =IF((BC5-BD5)<0,0,((BC5-BD5))) -> 7918.81 | BF5: =ROUND((AF5-AK5-BE5-AL5-AM5-AN5-AO5),2) -> 34035.87 | BH5: =VLOOKUP(C5,考勤!C:AL,36,0) -> ~@.com | BI5: =P5+Q5+R5+S5+T5-U5-V5+W5+X5+Y5+Z5+AA5+AB5+AC5+AD5-AG5-AH5-AI5-AJ5-AL5-AM5-AN5-AO5-BE5-BF5 -> 0
A6: =ROW()-2 -> 4 | B6: 创想悦动 | C6: SCX00004 | D6: 杨晓波 | E6: 合同制人员 | F6: 创想悦动 | G6: 基础产品部 | H6: 45880 | J6: 创想悦动-管理 | K6: 卡通动画 | L6: 1 | M6: 创想悦动-管理 | N6: 440881198504087112 | O6: 6225887813978158 | P6: 48000 | Q6: =ROUND(SUMIF(其他补发!B:B,$C6,其他补发!D:D),2) -> 0 | R6: =ROUND(SUMIF(其他补发!B:B,$C6,其他补发!H:H),2) -> 0 | S6: =ROUND(SUMIF(其他补发!B:B,$C6,其他补发!I:I),2) -> 0 | T6: =ROUND(SUMIF(其他补发!B:B,$C6,其他补发!E:E),2) -> 0 | U6: =ROUND((VLOOKUP(C6,考勤!C:H,6,0)+VLOOKUP(C6,考勤!C:O,13,0)+VLOOKUP(C6,考勤!C:P,14,0)*0.3+VLOOKUP(C6,考勤!C:AA,25,0))*(P6+Q6+R6)/21.75,2)+ROUND((VLOOKUP(C6,考勤!C:V,19,0)+VLOOKUP(C6,考勤!C:V,20,0))*(P6+Q6+R6-2520)/21.75,2) -> 0 | V6: =ROUND(SUMIF(动态表!C:C,C6,动态表!AA:AA)+SUMIFS(其他补发!L:L,其他补发!B:B,C6),2) -> 0 | W6: =ROUND(VLOOKUP(C6,考勤!C:K,9,0)*P6/21.75/8*2+VLOOKUP(C6,考勤!C:L,10,0)*P6/21.75/8*3,2)+SUMIFS(加班费!$H:$H,加班费!$D:$D,$C6) -> 0 | X6: =SUMIF(奖金!D:D,C6,奖金!F:F) -> 0 | Y6: =SUMIF(其他补发!B:B,C6,其他补发!J:J) -> 0 | Z6: =SUMIF(其他补发!B:B,C6,其他补发!F:F) -> 0 | AA6: =SUMIF(其他补发!B:B,C6,其他补发!G:G) -> 0 | AB6: =SUMIF(其他补发!B:B,C6,其他补发!M:M) -> 0 | AC6: =SUMIF(其他补发!B:B,C6,其他补发!N:N) -> 0 | AD6: =SUMIF(其他补发!B:B,C6,其他补发!K:K) -> 0 | AE6: =AD6+AC6+AB6+AA6+Z6+Y6+X6+W6 -> 0 | AF6: =ROUND((P6+Q6+R6+S6+T6-U6-V6+AE6),2) -> 48000 | AG6: =SUMIF(税后扣款!B:B,C6,税后扣款!E:E) -> 0 | AH6: =SUMIF(房租水电!A:A,C6,房租水电!C:C) -> 0 | AI6: =SUMIF(房租水电!A:A,C6,房租水电!D:D) -> 0 | AJ6: =SUMIF(税后扣款!B:B,C6,税后扣款!D:D) -> -240 | AK6: =AJ6+AI6+AH6+AG6 -> -240 | AL6: =SUMIF(社会保险!D:D,N6,社会保险!I:I) -> 2203.92 | AM6: =SUMIF(社会保险!D:D,N6,社会保险!J:J) -> 672.66 | AN6: =SUMIF(社会保险!D:D,N6,社会保险!K:K) -> 96 | AO6: =SUMIF(公积金!C:C,N6,公积金!L:L) -> 2655.9 | AP6: =SUMIF(专项扣除!$B:$B,$C6,专项扣除!D:D) -> 0 | AQ6: =SUMIF(专项扣除!$B:$B,$C6,专项扣除!E:E) -> 0 | AR6: =SUMIF(专项扣除!$B:$B,$C6,专项扣除!F:F) -> 0 | AS6: =SUMIF(专项扣除!$B:$B,$C6,专项扣除!G:G) -> 0 | AT6: =SUMIF(专项扣除!$B:$B,$C6,专项扣除!H:H) -> 0 | AU6: =SUMIF(专项扣除!$B:$B,$C6,专项扣除!I:I) -> 0 | AV6: =SUMIF(专项扣除!$B:$B,$C6,专项扣除!J:J) -> 0 | AW6: 5000 | AX6: =AL6+AM6+AN6+AO6+AW6 -> 10628.48 | AY6: =SUMIF(上月累计工资累计社保和公积金!C:C,C6,上月累计工资累计社保和公积金!E:E) -> 336500 | AZ6: =IF(E6="实习人员",(AY6+AF6)*80%,AY6+AF6) -> 384500 | BA6: =SUMIF(上月累计工资累计社保和公积金!C:C,C6,上月累计工资累计社保和公积金!K:K) -> 74347.73 | BB6: =BA6+AX6 -> 84976.21 | BC6: =ROUND(MAX((AZ6-BB6-AP6-AQ6-AR6-AS6-AT6-AU6-AV6)*0.01*{3,10,20,25,30,35,45}-{0,2520,16920,31920,52920,85920,181920},0),2) -> 42984.76 | BD6: =SUMIF(上月累计工资累计社保和公积金!C:C,C6,上月累计工资累计社保和公积金!L:L) -> 35510.45 | BE6: =IF((BC6-BD6)<0,0,((BC6-BD6))) -> 7474.31 | BF6: =ROUND((AF6-AK6-BE6-AL6-AM6-AN6-AO6),2) -> 35137.21 | BH6: =VLOOKUP(C6,考勤!C:AL,36,0) -> yangxiaobo@youdoogo.com | BI6: =P6+Q6+R6+S6+T6-U6-V6+W6+X6+Y6+Z6+AA6+AB6+AC6+AD6-AG6-AH6-AI6-AJ6-AL6-AM6-AN6-AO6-BE6-BF6 -> 0
A7: =ROW()-2 -> 5 | B7: 创想悦动 | C7: SCX00005 | D7: 杨振 | E7: 合同制人员 | F7: 创想悦动 | G7: 游戏研发部 | H7: 45880 | J7: 创想悦动-研发 | K7: 汉语言文学 | L7: 1 | M7: 创想悦动-研发 | N7: 110105197902051515 | O7: 6225886552211318 | P7: 45000 | Q7: =ROUND(SUMIF(其他补发!B:B,$C7,其他补发!D:D),2) -> 0 | R7: =ROUND(SUMIF(其他补发!B:B,$C7,其他补发!H:H),2) -> 0 | S7: =ROUND(SUMIF(其他补发!B:B,$C7,其他补发!I:I),2) -> 0 | T7: =ROUND(SUMIF(其他补发!B:B,$C7,其他补发!E:E),2) -> 0 | U7: =ROUND((VLOOKUP(C7,考勤!C:H,6,0)+VLOOKUP(C7,考勤!C:O,13,0)+VLOOKUP(C7,考勤!C:P,14,0)*0.3+VLOOKUP(C7,考勤!C:AA,25,0))*(P7+Q7+R7)/21.75,2)+ROUND((VLOOKUP(C7,考勤!C:V,19,0)+VLOOKUP(C7,考勤!C:V,20,0))*(P7+Q7+R7-2520)/21.75,2) -> 0 | V7: =ROUND(SUMIF(动态表!C:C,C7,动态表!AA:AA)+SUMIFS(其他补发!L:L,其他补发!B:B,C7),2) -> 0 | W7: =ROUND(VLOOKUP(C7,考勤!C:K,9,0)*P7/21.75/8*2+VLOOKUP(C7,考勤!C:L,10,0)*P7/21.75/8*3,2)+SUMIFS(加班费!$H:$H,加班费!$D:$D,$C7) -> 0 | X7: =SUMIF(奖金!D:D,C7,奖金!F:F) -> 0 | Y7: =SUMIF(其他补发!B:B,C7,其他补发!J:J) -> 0 | Z7: =SUMIF(其他补发!B:B,C7,其他补发!F:F) -> 0 | AA7: =SUMIF(其他补发!B:B,C7,其他补发!G:G) -> 0 | AB7: =SUMIF(其他补发!B:B,C7,其他补发!M:M) -> 0 | AC7: =SUMIF(其他补发!B:B,C7,其他补发!N:N) -> 0 | AD7: =SUMIF(其他补发!B:B,C7,其他补发!K:K) -> 0 | AE7: =AD7+AC7+AB7+AA7+Z7+Y7+X7+W7 -> 0 | AF7: =ROUND((P7+Q7+R7+S7+T7-U7-V7+AE7),2) -> 45000 | AG7: =SUMIF(税后扣款!B:B,C7,税后扣款!E:E) -> 0 | AH7: =SUMIF(房租水电!A:A,C7,房租水电!C:C) -> 0 | AI7: =SUMIF(房租水电!A:A,C7,房租水电!D:D) -> 0 | AJ7: =SUMIF(税后扣款!B:B,C7,税后扣款!D:D) -> -160 | AK7: =AJ7+AI7+AH7+AG7 -> -160 | AL7: =SUMIF(社会保险!D:D,N7,社会保险!I:I) -> 2203.92 | AM7: =SUMIF(社会保险!D:D,N7,社会保险!J:J) -> 672.66 | AN7: =SUMIF(社会保险!D:D,N7,社会保险!K:K) -> 90 | AO7: =SUMIF(公积金!C:C,N7,公积金!L:L) -> 2655.9 | AP7: =SUMIF(专项扣除!$B:$B,$C7,专项扣除!D:D) -> 0 | AQ7: =SUMIF(专项扣除!$B:$B,$C7,专项扣除!E:E) -> 0 | AR7: =SUMIF(专项扣除!$B:$B,$C7,专项扣除!F:F) -> 0 | AS7: =SUMIF(专项扣除!$B:$B,$C7,专项扣除!G:G) -> 0 | AT7: =SUMIF(专项扣除!$B:$B,$C7,专项扣除!H:H) -> 0 | AU7: =SUMIF(专项扣除!$B:$B,$C7,专项扣除!I:I) -> 0 | AV7: =SUMIF(专项扣除!$B:$B,$C7,专项扣除!J:J) -> 0 | AW7: 5000 | AX7: =AL7+AM7+AN7+AO7+AW7 -> 10622.48 | AY7: =SUMIF(上月累计工资累计社保和公积金!C:C,C7,上月累计工资累计社保和公积金!E:E) -> 315300 | AZ7: =IF(E7="实习人员",(AY7+AF7)*80%,AY7+AF7) -> 360300 | BA7: =SUMIF(上月累计工资累计社保和公积金!C:C,C7,上月累计工资累计社保和公积金!K:K) -> 74347.73 | BB7: =BA7+AX7 -> 84970.21 | BC7: =ROUND(MAX((AZ7-BB7-AP7-AQ7-AR7-AS7-AT7-AU7-AV7)*0.01*{3,10,20,25,30,35,45}-{0,2520,16920,31920,52920,85920,181920},0),2) -> 38145.96 | BD7: =SUMIF(上月累计工资累计社保和公积金!C:C,C7,上月累计工资累计社保和公积金!L:L) -> 31270.45 | BE7: =IF((BC7-BD7)<0,0,((BC7-BD7))) -> 6875.51 | BF7: =ROUND((AF7-AK7-BE7-AL7-AM7-AN7-AO7),2) -> 32662.01 | BH7: =VLOOKUP(C7,考勤!C:AL,36,0) -> ~@.com | BI7: =P7+Q7+R7+S7+T7-U7-V7+W7+X7+Y7+Z7+AA7+AB7+AC7+AD7-AG7-AH7-AI7-AJ7-AL7-AM7-AN7-AO7-BE7-BF7 -> 0
A8: =ROW()-2 -> 6 | B8: 创想悦动 | C8: SCX00006 | D8: 蔡昕宇 | E8: 合同制人员 | F8: 创想悦动 | G8: 商务合作部 | H8: 45880 | J8: 创想悦动-管理 | K8: 网络工程 | L8: 1 | M8: 创想悦动-管理 | N8: 210102198602153412 | O8: 6214867829480822 | P8: 38000 | Q8: =ROUND(SUMIF(其他补发!B:B,$C8,其他补发!D:D),2) -> 0 | R8: =ROUND(SUMIF(其他补发!B:B,$C8,其他补发!H:H),2) -> 0 | S8: =ROUND(SUMIF(其他补发!B:B,$C8,其他补发!I:I),2) -> 0 | T8: =ROUND(SUMIF(其他补发!B:B,$C8,其他补发!E:E),2) -> 0 | U8: =ROUND((VLOOKUP(C8,考勤!C:H,6,0)+VLOOKUP(C8,考勤!C:O,13,0)+VLOOKUP(C8,考勤!C:P,14,0)*0.3+VLOOKUP(C8,考勤!C:AA,25,0))*(P8+Q8+R8)/21.75,2)+ROUND((VLOOKUP(C8,考勤!C:V,19,0)+VLOOKUP(C8,考勤!C:V,20,0))*(P8+Q8+R8-2520)/21.75,2) -> 0 | V8: =ROUND(SUMIF(动态表!C:C,C8,动态表!AA:AA)+SUMIFS(其他补发!L:L,其他补发!B:B,C8),2) -> 0 | W8: =ROUND(VLOOKUP(C8,考勤!C:K,9,0)*P8/21.75/8*2+VLOOKUP(C8,考勤!C:L,10,0)*P8/21.75/8*3,2)+SUMIFS(加班费!$H:$H,加班费!$D:$D,$C8) -> 0 | X8: =SUMIF(奖金!D:D,C8,奖金!F:F) -> 0 | Y8: =SUMIF(其他补发!B:B,C8,其他补发!J:J) -> 0 | Z8: =SUMIF(其他补发!B:B,C8,其他补发!F:F) -> 0 | AA8: =SUMIF(其他补发!B:B,C8,其他补发!G:G) -> 0 | AB8: =SUMIF(其他补发!B:B,C8,其他补发!M:M) -> 0 | AC8: =SUMIF(其他补发!B:B,C8,其他补发!N:N) -> 0 | AD8: =SUMIF(其他补发!B:B,C8,其他补发!K:K) -> 0 | AE8: =AD8+AC8+AB8+AA8+Z8+Y8+X8+W8 -> 0 | AF8: =ROUND((P8+Q8+R8+S8+T8-U8-V8+AE8),2) -> 38000 | AG8: =SUMIF(税后扣款!B:B,C8,税后扣款!E:E) -> 0 | AH8: =SUMIF(房租水电!A:A,C8,房租水电!C:C) -> 0 | AI8: =SUMIF(房租水电!A:A,C8,房租水电!D:D) -> 0 | AJ8: =SUMIF(税后扣款!B:B,C8,税后扣款!D:D) -> -160 | AK8: =AJ8+AI8+AH8+AG8 -> -160 | AL8: =SUMIF(社会保险!D:D,N8,社会保险!I:I) -> 0 | AM8: =SUMIF(社会保险!D:D,N8,社会保险!J:J) -> 0 | AN8: =SUMIF(社会保险!D:D,N8,社会保险!K:K) -> 0 | AO8: =SUMIF(公积金!C:C,N8,公积金!L:L) -> 0 | AP8: =SUMIF(专项扣除!$B:$B,$C8,专项扣除!D:D) -> 0 | AQ8: =SUMIF(专项扣除!$B:$B,$C8,专项扣除!E:E) -> 0 | AR8: =SUMIF(专项扣除!$B:$B,$C8,专项扣除!F:F) -> 0 | AS8: =SUMIF(专项扣除!$B:$B,$C8,专项扣除!G:G) -> 0 | AT8: =SUMIF(专项扣除!$B:$B,$C8,专项扣除!H:H) -> 0 | AU8: =SUMIF(专项扣除!$B:$B,$C8,专项扣除!I:I) -> 0 | AV8: =SUMIF(专项扣除!$B:$B,$C8,专项扣除!J:J) -> 0 | AW8: 5000 | AX8: =AL8+AM8+AN8+AO8+AW8 -> 5000 | AY8: =SUMIF(上月累计工资累计社保和公积金!C:C,C8,上月累计工资累计社保和公积金!E:E) -> 254300 | AZ8: =IF(E8="实习人员",(AY8+AF8)*80%,AY8+AF8) -> 292300 | BA8: =SUMIF(上月累计工资累计社保和公积金!C:C,C8,上月累计工资累计社保和公积金!K:K) -> 35000 | BB8: =BA8+AX8 -> 40000 | BC8: =ROUND(MAX((AZ8-BB8-AP8-AQ8-AR8-AS8-AT8-AU8-AV8)*0.01*{3,10,20,25,30,35,45}-{0,2520,16920,31920,52920,85920,181920},0),2) -> 33540 | BD8: =SUMIF(上月累计工资累计社保和公积金!C:C,C8,上月累计工资累计社保和公积金!L:L) -> 26940 | BE8: =IF((BC8-BD8)<0,0,((BC8-BD8))) -> 6600 | BF8: =ROUND((AF8-AK8-BE8-AL8-AM8-AN8-AO8),2) -> 31560 | BH8: =VLOOKUP(C8,考勤!C:AL,36,0) -> Simon@youdoogo.com | BI8: =P8+Q8+R8+S8+T8-U8-V8+W8+X8+Y8+Z8+AA8+AB8+AC8+AD8-AG8-AH8-AI8-AJ8-AL8-AM8-AN8-AO8-BE8-BF8 -> 0
A9: =ROW()-2 -> 7 | B9: 创想悦动 | C9: SCX00007 | D9: 廖斌 | E9: 合同制人员 | F9: 创想悦动 | G9: 游戏研发部 | H9: 45880 | J9: 创想悦动-研发 | K9: 经济管理学 | L9: 1 | M9: 创想悦动-研发 | N9: 350824199212280012 | O9: 6214851800394657 | P9: 18000 | Q9: =ROUND(SUMIF(其他补发!B:B,$C9,其他补发!D:D),2) -> 0 | R9: =ROUND(SUMIF(其他补发!B:B,$C9,其他补发!H:H),2) -> 0 | S9: =ROUND(SUMIF(其他补发!B:B,$C9,其他补发!I:I),2) -> 0 | T9: =ROUND(SUMIF(其他补发!B:B,$C9,其他补发!E:E),2) -> 0 | U9: =ROUND((VLOOKUP(C9,考勤!C:H,6,0)+VLOOKUP(C9,考勤!C:O,13,0)+VLOOKUP(C9,考勤!C:P,14,0)*0.3+VLOOKUP(C9,考勤!C:AA,25,0))*(P9+Q9+R9)/21.75,2)+ROUND((VLOOKUP(C9,考勤!C:V,19,0)+VLOOKUP(C9,考勤!C:V,20,0))*(P9+Q9+R9-2520)/21.75,2) -> 0 | V9: =ROUND(SUMIF(动态表!C:C,C9,动态表!AA:AA)+SUMIFS(其他补发!L:L,其他补发!B:B,C9),2) -> 0 | W9: =ROUND(VLOOKUP(C9,考勤!C:K,9,0)*P9/21.75/8*2+VLOOKUP(C9,考勤!C:L,10,0)*P9/21.75/8*3,2)+SUMIFS(加班费!$H:$H,加班费!$D:$D,$C9) -> 0 | X9: =SUMIF(奖金!D:D,C9,奖金!F:F) -> 0 | Y9: =SUMIF(其他补发!B:B,C9,其他补发!J:J) -> 0 | Z9: =SUMIF(其他补发!B:B,C9,其他补发!F:F) -> 0 | AA9: =SUMIF(其他补发!B:B,C9,其他补发!G:G) -> 0 | AB9: =SUMIF(其他补发!B:B,C9,其他补发!M:M) -> 0 | AC9: =SUMIF(其他补发!B:B,C9,其他补发!N:N) -> 0 | AD9: =SUMIF(其他补发!B:B,C9,其他补发!K:K) -> 0 | AE9: =AD9+AC9+AB9+AA9+Z9+Y9+X9+W9 -> 0 | AF9: =ROUND((P9+Q9+R9+S9+T9-U9-V9+AE9),2) -> 18000 | AG9: =SUMIF(税后扣款!B:B,C9,税后扣款!E:E) -> 0 | AH9: =SUMIF(房租水电!A:A,C9,房租水电!C:C) -> 0 | AI9: =SUMIF(房租水电!A:A,C9,房租水电!D:D) -> 0 | AJ9: =SUMIF(税后扣款!B:B,C9,税后扣款!D:D) -> 0 | AK9: =AJ9+AI9+AH9+AG9 -> 0 | AL9: =SUMIF(社会保险!D:D,N9,社会保险!I:I) -> 1440 | AM9: =SUMIF(社会保险!D:D,N9,社会保险!J:J) -> 360 | AN9: =SUMIF(社会保险!D:D,N9,社会保险!K:K) -> 36 | AO9: =SUMIF(公积金!C:C,N9,公积金!L:L) -> 2160 | AP9: =SUMIF(专项扣除!$B:$B,$C9,专项扣除!D:D) -> 0 | AQ9: =SUMIF(专项扣除!$B:$B,$C9,专项扣除!E:E) -> 0 | AR9: =SUMIF(专项扣除!$B:$B,$C9,专项扣除!F:F) -> 0 | AS9: =SUMIF(专项扣除!$B:$B,$C9,专项扣除!G:G) -> 0 | AT9: =SUMIF(专项扣除!$B:$B,$C9,专项扣除!H:H) -> 0 | AU9: =SUMIF(专项扣除!$B:$B,$C9,专项扣除!I:I) -> 0 | AV9: =SUMIF(专项扣除!$B:$B,$C9,专项扣除!J:J) -> 0 | AW9: 5000 | AX9: =AL9+AM9+AN9+AO9+AW9 -> 8996 | AY9: =SUMIF(上月累计工资累计社保和公积金!C:C,C9,上月累计工资累计社保和公积金!E:E) -> 126300 | AZ9: =IF(E9="实习人员",(AY9+AF9)*80%,AY9+AF9) -> 144300 | BA9: =SUMIF(上月累计工资累计社保和公积金!C:C,C9,上月累计工资累计社保和公积金!K:K) -> 55412 | BB9: =BA9+AX9 -> 64408 | BC9: =ROUND(MAX((AZ9-BB9-AP9-AQ9-AR9-AS9-AT9-AU9-AV9)*0.01*{3,10,20,25,30,35,45}-{0,2520,16920,31920,52920,85920,181920},0),2) -> 5469.2 | BD9: =SUMIF(上月累计工资累计社保和公积金!C:C,C9,上月累计工资累计社保和公积金!L:L) -> 4568.8 | BE9: =IF((BC9-BD9)<0,0,((BC9-BD9))) -> 900.4 | BF9: =ROUND((AF9-AK9-BE9-AL9-AM9-AN9-AO9),2) -> 13103.6 | BH9: =VLOOKUP(C9,考勤!C:AL,36,0) -> ~@.com | BI9: =P9+Q9+R9+S9+T9-U9-V9+W9+X9+Y9+Z9+AA9+AB9+AC9+AD9-AG9-AH9-AI9-AJ9-AL9-AM9-AN9-AO9-BE9-BF9 -> 0
A10: =ROW()-2 -> 8 | B10: 创想悦动 | C10: SCX00008 | D10: 刘奎廷 | E10: 合同制人员 | F10: 创想悦动 | G10: 基础产品部 | H10: 45880 | J10: 创想悦动-研发 | K10: 计算机科学与技术 | L10: 1 | M10: 创想悦动-研发 | N10: 440921198308169216 | O10: 6214867555311811 | P10: 30000 | Q10: =ROUND(SUMIF(其他补发!B:B,$C10,其他补发!D:D),2) -> 0 | R10: =ROUND(SUMIF(其他补发!B:B,$C10,其他补发!H:H),2) -> 0 | S10: =ROUND(SUMIF(其他补发!B:B,$C10,其他补发!I:I),2) -> 0 | T10: =ROUND(SUMIF(其他补发!B:B,$C10,其他补发!E:E),2) -> 0 | U10: =ROUND((VLOOKUP(C10,考勤!C:H,6,0)+VLOOKUP(C10,考勤!C:O,13,0)+VLOOKUP(C10,考勤!C:P,14,0)*0.3+VLOOKUP(C10,考勤!C:AA,25,0))*(P10+Q10+R10)/21.75,2)+ROUND((VLOOKUP(C10,考勤!C:V,19,0)+VLOOKUP(C10,考勤!C:V,20,0))*(P10+Q10+R10-2520)/21.75,2) -> 0 | V10: =ROUND(SUMIF(动态表!C:C,C10,动态表!AA:AA)+SUMIFS(其他补发!L:L,其他补发!B:B,C10),2) -> 0 | W10: =ROUND(VLOOKUP(C10,考勤!C:K,9,0)*P10/21.75/8*2+VLOOKUP(C10,考勤!C:L,10,0)*P10/21.75/8*3,2)+SUMIFS(加班费!$H:$H,加班费!$D:$D,$C10) -> 0 | X10: =SUMIF(奖金!D:D,C10,奖金!F:F) -> 0 | Y10: =SUMIF(其他补发!B:B,C10,其他补发!J:J) -> 0 | Z10: =SUMIF(其他补发!B:B,C10,其他补发!F:F) -> 0 | AA10: =SUMIF(其他补发!B:B,C10,其他补发!G:G) -> 0 | AB10: =SUMIF(其他补发!B:B,C10,其他补发!M:M) -> 0 | AC10: =SUMIF(其他补发!B:B,C10,其他补发!N:N) -> 0 | AD10: =SUMIF(其他补发!B:B,C10,其他补发!K:K) -> 0 | AE10: =AD10+AC10+AB10+AA10+Z10+Y10+X10+W10 -> 0 | AF10: =ROUND((P10+Q10+R10+S10+T10-U10-V10+AE10),2) -> 30000 | AG10: =SUMIF(税后扣款!B:B,C10,税后扣款!E:E) -> 0 | AH10: =SUMIF(房租水电!A:A,C10,房租水电!C:C) -> 0 | AI10: =SUMIF(房租水电!A:A,C10,房租水电!D:D) -> 0 | AJ10: =SUMIF(税后扣款!B:B,C10,税后扣款!D:D) -> 0 | AK10: =AJ10+AI10+AH10+AG10 -> 0 | AL10: =SUMIF(社会保险!D:D,N10,社会保险!I:I) -> 2203.92 | AM10: =SUMIF(社会保险!D:D,N10,社会保险!J:J) -> 600 | AN10: =SUMIF(社会保险!D:D,N10,社会保险!K:K) -> 60 | AO10: =SUMIF(公积金!C:C,N10,公积金!L:L) -> 3600 | AP10: =SUMIF(专项扣除!$B:$B,$C10,专项扣除!D:D) -> 0 | AQ10: =SUMIF(专项扣除!$B:$B,$C10,专项扣除!E:E) -> 0 | AR10: =SUMIF(专项扣除!$B:$B,$C10,专项扣除!F:F) -> 0 | AS10: =SUMIF(专项扣除!$B:$B,$C10,专项扣除!G:G) -> 0 | AT10: =SUMIF(专项扣除!$B:$B,$C10,专项扣除!H:H) -> 0 | AU10: =SUMIF(专项扣除!$B:$B,$C10,专项扣除!I:I) -> 0 | AV10: =SUMIF(专项扣除!$B:$B,$C10,专项扣除!J:J) -> 0 | AW10: 5000 | AX10: =AL10+AM10+AN10+AO10+AW10 -> 11463.92 | AY10: =SUMIF(上月累计工资累计社保和公积金!C:C,C10,上月累计工资累计社保和公积金!E:E) -> 210300 | AZ10: =IF(E10="实习人员",(AY10+AF10)*80%,AY10+AF10) -> 240300 | BA10: =SUMIF(上月累计工资累计社保和公积金!C:C,C10,上月累计工资累计社保和公积金!K:K) -> 67647.44 | BB10: =BA10+AX10 -> 79111.36 | BC10: =ROUND(MAX((AZ10-BB10-AP10-AQ10-AR10-AS10-AT10-AU10-AV10)*0.01*{3,10,20,25,30,35,45}-{0,2520,16920,31920,52920,85920,181920},0),2) -> 15317.73 | BD10: =SUMIF(上月累计工资累计社保和公积金!C:C,C10,上月累计工资累计社保和公积金!L:L) -> 11745.26 | BE10: =IF((BC10-BD10)<0,0,((BC10-BD10))) -> 3572.47 | BF10: =ROUND((AF10-AK10-BE10-AL10-AM10-AN10-AO10),2) -> 19963.61 | BH10: =VLOOKUP(C10,考勤!C:AL,36,0) -> LiuKuiTing@.com | BI10: =P10+Q10+R10+S10+T10-U10-V10+W10+X10+Y10+Z10+AA10+AB10+AC10+AD10-AG10-AH10-AI10-AJ10-AL10-AM10-AN10-AO10-BE10-BF10 -> 0
A11: =ROW()-2 -> 9 | B11: 创想悦动 | C11: SCX00012 | D11: 张磊 | E11: 合同制人员 | F11: 创想悦动 | G11: 基础产品部 | H11: 45880 | J11: 创想悦动-研发 | K11: 计算机科学与技术 | L11: 1 | M11: 创想悦动-研发 | N11: 610422198511200056 | O11: 6225887837426135 | P11: 30000 | Q11: =ROUND(SUMIF(其他补发!B:B,$C11,其他补发!D:D),2) -> 0 | R11: =ROUND(SUMIF(其他补发!B:B,$C11,其他补发!H:H),2) -> 0 | S11: =ROUND(SUMIF(其他补发!B:B,$C11,其他补发!I:I),2) -> 0 | T11: =ROUND(SUMIF(其他补发!B:B,$C11,其他补发!E:E),2) -> 0 | U11: =ROUND((VLOOKUP(C11,考勤!C:H,6,0)+VLOOKUP(C11,考勤!C:O,13,0)+VLOOKUP(C11,考勤!C:P,14,0)*0.3+VLOOKUP(C11,考勤!C:AA,25,0))*(P11+Q11+R11)/21.75,2)+ROUND((VLOOKUP(C11,考勤!C:V,19,0)+VLOOKUP(C11,考勤!C:V,20,0))*(P11+Q11+R11-2520)/21.75,2) -> 0 | V11: =ROUND(SUMIF(动态表!C:C,C11,动态表!AA:AA)+SUMIFS(其他补发!L:L,其他补发!B:B,C11),2) -> 0 | W11: =ROUND(VLOOKUP(C11,考勤!C:K,9,0)*P11/21.75/8*2+VLOOKUP(C11,考勤!C:L,10,0)*P11/21.75/8*3,2)+SUMIFS(加班费!$H:$H,加班费!$D:$D,$C11) -> 0 | X11: =SUMIF(奖金!D:D,C11,奖金!F:F) -> 0 | Y11: =SUMIF(其他补发!B:B,C11,其他补发!J:J) -> 0 | Z11: =SUMIF(其他补发!B:B,C11,其他补发!F:F) -> 0 | AA11: =SUMIF(其他补发!B:B,C11,其他补发!G:G) -> 0 | AB11: =SUMIF(其他补发!B:B,C11,其他补发!M:M) -> 0 | AC11: =SUMIF(其他补发!B:B,C11,其他补发!N:N) -> 0 | AD11: =SUMIF(其他补发!B:B,C11,其他补发!K:K) -> 0 | AE11: =AD11+AC11+AB11+AA11+Z11+Y11+X11+W11 -> 0 | AF11: =ROUND((P11+Q11+R11+S11+T11-U11-V11+AE11),2) -> 30000 | AG11: =SUMIF(税后扣款!B:B,C11,税后扣款!E:E) -> 0 | AH11: =SUMIF(房租水电!A:A,C11,房租水电!C:C) -> 0 | AI11: =SUMIF(房租水电!A:A,C11,房租水电!D:D) -> 0 | AJ11: =SUMIF(税后扣款!B:B,C11,税后扣款!D:D) -> 0 | AK11: =AJ11+AI11+AH11+AG11 -> 0 | AL11: =SUMIF(社会保险!D:D,N11,社会保险!I:I) -> 2203.92 | AM11: =SUMIF(社会保险!D:D,N11,社会保险!J:J) -> 600 | AN11: =SUMIF(社会保险!D:D,N11,社会保险!K:K) -> 60 | AO11: =SUMIF(公积金!C:C,N11,公积金!L:L) -> 3600 | AP11: =SUMIF(专项扣除!$B:$B,$C11,专项扣除!D:D) -> 0 | AQ11: =SUMIF(专项扣除!$B:$B,$C11,专项扣除!E:E) -> 0 | AR11: =SUMIF(专项扣除!$B:$B,$C11,专项扣除!F:F) -> 0 | AS11: =SUMIF(专项扣除!$B:$B,$C11,专项扣除!G:G) -> 0 | AT11: =SUMIF(专项扣除!$B:$B,$C11,专项扣除!H:H) -> 0 | AU11: =SUMIF(专项扣除!$B:$B,$C11,专项扣除!I:I) -> 0 | AV11: =SUMIF(专项扣除!$B:$B,$C11,专项扣除!J:J) -> 0 | AW11: 5000 | AX11: =AL11+AM11+AN11+AO11+AW11 -> 11463.92 | AY11: =SUMIF(上月累计工资累计社保和公积金!C:C,C11,上月累计工资累计社保和公积金!E:E) -> 210300 | AZ11: =IF(E11="实习人员",(AY11+AF11)*80%,AY11+AF11) -> 240300 | BA11: =SUMIF(上月累计工资累计社保和公积金!C:C,C11,上月累计工资累计社保和公积金!K:K) -> 67647.44 | BB11: =BA11+AX11 -> 79111.36 | BC11: =ROUND(MAX((AZ11-BB11-AP11-AQ11-AR11-AS11-AT11-AU11-AV11)*0.01*{3,10,20,25,30,35,45}-{0,2520,16920,31920,52920,85920,181920},0),2) -> 15317.73 | BD11: =SUMIF(上月累计工资累计社保和公积金!C:C,C11,上月累计工资累计社保和公积金!L:L) -> 11745.26 | BE11: =IF((BC11-BD11)<0,0,((BC11-BD11))) -> 3572.47 | BF11: =ROUND((AF11-AK11-BE11-AL11-AM11-AN11-AO11),2) -> 19963.61 | BH11: =VLOOKUP(C11,考勤!C:AL,36,0) -> Red@youdoogo.com | BI11: =P11+Q11+R11+S11+T11-U11-V11+W11+X11+Y11+Z11+AA11+AB11+AC11+AD11-AG11-AH11-AI11-AJ11-AL11-AM11-AN11-AO11-BE11-BF11 -> 0
A12: =ROW()-2 -> 10 | B12: 创想悦动 | C12: SCX00014 | D12: 杨东升 | E12: 合同制人员 | F12: 创想悦动 | G12: 游戏研发部 | H12: 45880 | J12: 创想悦动-研发 | K12: 电子信息工程 | L12: 1 | M12: 创想悦动-研发 | N12: 610124199909050917 | O12: 6214830506177103 | P12: 20000 | Q12: =ROUND(SUMIF(其他补发!B:B,$C12,其他补发!D:D),2) -> 0 | R12: =ROUND(SUMIF(其他补发!B:B,$C12,其他补发!H:H),2) -> 0 | S12: =ROUND(SUMIF(其他补发!B:B,$C12,其他补发!I:I),2) -> 0 | T12: =ROUND(SUMIF(其他补发!B:B,$C12,其他补发!E:E),2) -> 0 | U12: =ROUND((VLOOKUP(C12,考勤!C:H,6,0)+VLOOKUP(C12,考勤!C:O,13,0)+VLOOKUP(C12,考勤!C:P,14,0)*0.3+VLOOKUP(C12,考勤!C:AA,25,0))*(P12+Q12+R12)/21.75,2)+ROUND((VLOOKUP(C12,考勤!C:V,19,0)+VLOOKUP(C12,考勤!C:V,20,0))*(P12+Q12+R12-2520)/21.75,2) -> 0 | V12: =ROUND(SUMIF(动态表!C:C,C12,动态表!AA:AA)+SUMIFS(其他补发!L:L,其他补发!B:B,C12),2) -> 0 | W12: =ROUND(VLOOKUP(C12,考勤!C:K,9,0)*P12/21.75/8*2+VLOOKUP(C12,考勤!C:L,10,0)*P12/21.75/8*3,2)+SUMIFS(加班费!$H:$H,加班费!$D:$D,$C12) -> 0 | X12: =SUMIF(奖金!D:D,C12,奖金!F:F) -> 0 | Y12: =SUMIF(其他补发!B:B,C12,其他补发!J:J) -> 0 | Z12: =SUMIF(其他补发!B:B,C12,其他补发!F:F) -> 0 | AA12: =SUMIF(其他补发!B:B,C12,其他补发!G:G) -> 0 | AB12: =SUMIF(其他补发!B:B,C12,其他补发!M:M) -> 0 | AC12: =SUMIF(其他补发!B:B,C12,其他补发!N:N) -> 0 | AD12: =SUMIF(其他补发!B:B,C12,其他补发!K:K) -> 0 | AE12: =AD12+AC12+AB12+AA12+Z12+Y12+X12+W12 -> 0 | AF12: =ROUND((P12+Q12+R12+S12+T12-U12-V12+AE12),2) -> 20000 | AG12: =SUMIF(税后扣款!B:B,C12,税后扣款!E:E) -> 0 | AH12: =SUMIF(房租水电!A:A,C12,房租水电!C:C) -> 0 | AI12: =SUMIF(房租水电!A:A,C12,房租水电!D:D) -> 0 | AJ12: =SUMIF(税后扣款!B:B,C12,税后扣款!D:D) -> 0 | AK12: =AJ12+AI12+AH12+AG12 -> 0 | AL12: =SUMIF(社会保险!D:D,N12,社会保险!I:I) -> 1600 | AM12: =SUMIF(社会保险!D:D,N12,社会保险!J:J) -> 400 | AN12: =SUMIF(社会保险!D:D,N12,社会保险!K:K) -> 40 | AO12: =SUMIF(公积金!C:C,N12,公积金!L:L) -> 1200 | AP12: =SUMIF(专项扣除!$B:$B,$C12,专项扣除!D:D) -> 0 | AQ12: =SUMIF(专项扣除!$B:$B,$C12,专项扣除!E:E) -> 0 | AR12: =SUMIF(专项扣除!$B:$B,$C12,专项扣除!F:F) -> 0 | AS12: =SUMIF(专项扣除!$B:$B,$C12,专项扣除!G:G) -> 0 | AT12: =SUMIF(专项扣除!$B:$B,$C12,专项扣除!H:H) -> 0 | AU12: =SUMIF(专项扣除!$B:$B,$C12,专项扣除!I:I) -> 0 | AV12: =SUMIF(专项扣除!$B:$B,$C12,专项扣除!J:J) -> 0 | AW12: 5000 | AX12: =AL12+AM12+AN12+AO12+AW12 -> 8240 | AY12: =SUMIF(上月累计工资累计社保和公积金!C:C,C12,上月累计工资累计社保和公积金!E:E) -> 140300 | AZ12: =IF(E12="实习人员",(AY12+AF12)*80%,AY12+AF12) -> 160300 | BA12: =SUMIF(上月累计工资累计社保和公积金!C:C,C12,上月累计工资累计社保和公积金!K:K) -> 57680 | BB12: =BA12+AX12 -> 65920 | BC12: =ROUND(MAX((AZ12-BB12-AP12-AQ12-AR12-AS12-AT12-AU12-AV12)*0.01*{3,10,20,25,30,35,45}-{0,2520,16920,31920,52920,85920,181920},0),2) -> 6918 | BD12: =SUMIF(上月累计工资累计社保和公积金!C:C,C12,上月累计工资累计社保和公积金!L:L) -> 5742 | BE12: =IF((BC12-BD12)<0,0,((BC12-BD12))) -> 1176 | BF12: =ROUND((AF12-AK12-BE12-AL12-AM12-AN12-AO12),2) -> 15584 | BH12: =VLOOKUP(C12,考勤!C:AL,36,0) -> ~@.com | BI12: =P12+Q12+R12+S12+T12-U12-V12+W12+X12+Y12+Z12+AA12+AB12+AC12+AD12-AG12-AH12-AI12-AJ12-AL12-AM12-AN12-AO12-BE12-BF12 -> 0
A13: =ROW()-2 -> 11 | B13: 创想悦动 | C13: SCX00015 | D13: 陈曦 | E13: 合同制人员 | F13: 创想悦动 | G13: 商务合作部 | H13: 45880 | J13: 创想悦动-销售 | K13: 计算机科学与技术 | L13: 1 | M13: 创想悦动-销售 | N13: 120106198508234519 | O13: 6226096550170206 | P13: 25000 | Q13: =ROUND(SUMIF(其他补发!B:B,$C13,其他补发!D:D),2) -> 0 | R13: =ROUND(SUMIF(其他补发!B:B,$C13,其他补发!H:H),2) -> 0 | S13: =ROUND(SUMIF(其他补发!B:B,$C13,其他补发!I:I),2) -> 0 | T13: =ROUND(SUMIF(其他补发!B:B,$C13,其他补发!E:E),2) -> 0 | U13: =ROUND((VLOOKUP(C13,考勤!C:H,6,0)+VLOOKUP(C13,考勤!C:O,13,0)+VLOOKUP(C13,考勤!C:P,14,0)*0.3+VLOOKUP(C13,考勤!C:AA,25,0))*(P13+Q13+R13)/21.75,2)+ROUND((VLOOKUP(C13,考勤!C:V,19,0)+VLOOKUP(C13,考勤!C:V,20,0))*(P13+Q13+R13-2520)/21.75,2) -> 0 | V13: =ROUND(SUMIF(动态表!C:C,C13,动态表!AA:AA)+SUMIFS(其他补发!L:L,其他补发!B:B,C13),2) -> 0 | W13: =ROUND(VLOOKUP(C13,考勤!C:K,9,0)*P13/21.75/8*2+VLOOKUP(C13,考勤!C:L,10,0)*P13/21.75/8*3,2)+SUMIFS(加班费!$H:$H,加班费!$D:$D,$C13) -> 0 | X13: =SUMIF(奖金!D:D,C13,奖金!F:F) -> 0 | Y13: =SUMIF(其他补发!B:B,C13,其他补发!J:J) -> 0 | Z13: =SUMIF(其他补发!B:B,C13,其他补发!F:F) -> 0 | AA13: =SUMIF(其他补发!B:B,C13,其他补发!G:G) -> 0 | AB13: =SUMIF(其他补发!B:B,C13,其他补发!M:M) -> 0 | AC13: =SUMIF(其他补发!B:B,C13,其他补发!N:N) -> 0 | AD13: =SUMIF(其他补发!B:B,C13,其他补发!K:K) -> 0 | AE13: =AD13+AC13+AB13+AA13+Z13+Y13+X13+W13 -> 0 | AF13: =ROUND((P13+Q13+R13+S13+T13-U13-V13+AE13),2) -> 25000 | AG13: =SUMIF(税后扣款!B:B,C13,税后扣款!E:E) -> 0 | AH13: =SUMIF(房租水电!A:A,C13,房租水电!C:C) -> 0 | AI13: =SUMIF(房租水电!A:A,C13,房租水电!D:D) -> 0 | AJ13: =SUMIF(税后扣款!B:B,C13,税后扣款!D:D) -> 0 | AK13: =AJ13+AI13+AH13+AG13 -> 0 | AL13: =SUMIF(社会保险!D:D,N13,社会保险!I:I) -> 2000 | AM13: =SUMIF(社会保险!D:D,N13,社会保险!J:J) -> 500 | AN13: =SUMIF(社会保险!D:D,N13,社会保险!K:K) -> 50 | AO13: =SUMIF(公积金!C:C,N13,公积金!L:L) -> 1500 | AP13: =SUMIF(专项扣除!$B:$B,$C13,专项扣除!D:D) -> 0 | AQ13: =SUMIF(专项扣除!$B:$B,$C13,专项扣除!E:E) -> 0 | AR13: =SUMIF(专项扣除!$B:$B,$C13,专项扣除!F:F) -> 0 | AS13: =SUMIF(专项扣除!$B:$B,$C13,专项扣除!G:G) -> 0 | AT13: =SUMIF(专项扣除!$B:$B,$C13,专项扣除!H:H) -> 0 | AU13: =SUMIF(专项扣除!$B:$B,$C13,专项扣除!I:I) -> 0 | AV13: =SUMIF(专项扣除!$B:$B,$C13,专项扣除!J:J) -> 0 | AW13: 5000 | AX13: =AL13+AM13+AN13+AO13+AW13 -> 9050 | AY13: =SUMIF(上月累计工资累计社保和公积金!C:C,C13,上月累计工资累计社保和公积金!E:E) -> 176050 | AZ13: =IF(E13="实习人员",(AY13+AF13)*80%,AY13+AF13) -> 201050 | BA13: =SUMIF(上月累计工资累计社保和公积金!C:C,C13,上月累计工资累计社保和公积金!K:K) -> 63350 | BB13: =BA13+AX13 -> 72400 | BC13: =ROUND(MAX((AZ13-BB13-AP13-AQ13-AR13-AS13-AT13-AU13-AV13)*0.01*{3,10,20,25,30,35,45}-{0,2520,16920,31920,52920,85920,181920},0),2) -> 10345 | BD13: =SUMIF(上月累计工资累计社保和公积金!C:C,C13,上月累计工资累计社保和公积金!L:L) -> 8750 | BE13: =IF((BC13-BD13)<0,0,((BC13-BD13))) -> 1595 | BF13: =ROUND((AF13-AK13-BE13-AL13-AM13-AN13-AO13),2) -> 19355 | BH13: =VLOOKUP(C13,考勤!C:AL,36,0) -> ～@.com | BI13: =P13+Q13+R13+S13+T13-U13-V13+W13+X13+Y13+Z13+AA13+AB13+AC13+AD13-AG13-AH13-AI13-AJ13-AL13-AM13-AN13-AO13-BE13-BF13 -> 0
A14: =ROW()-2 -> 12 | B14: 创想悦动 | C14: SCX00016 | D14: 胡豪 | E14: 合同制人员 | F14: 创想悦动 | G14: 游戏研发部 | H14: 45880 | J14: 创想悦动-研发 | K14: 生物技术 | L14: 1 | M14: 创想悦动-研发 | N14: 362401199603151514 | O14: 6214838652728835 | P14: 23000 | Q14: =ROUND(SUMIF(其他补发!B:B,$C14,其他补发!D:D),2) -> 0 | R14: =ROUND(SUMIF(其他补发!B:B,$C14,其他补发!H:H),2) -> 0 | S14: =ROUND(SUMIF(其他补发!B:B,$C14,其他补发!I:I),2) -> 0 | T14: =ROUND(SUMIF(其他补发!B:B,$C14,其他补发!E:E),2) -> 0 | U14: =ROUND((VLOOKUP(C14,考勤!C:H,6,0)+VLOOKUP(C14,考勤!C:O,13,0)+VLOOKUP(C14,考勤!C:P,14,0)*0.3+VLOOKUP(C14,考勤!C:AA,25,0))*(P14+Q14+R14)/21.75,2)+ROUND((VLOOKUP(C14,考勤!C:V,19,0)+VLOOKUP(C14,考勤!C:V,20,0))*(P14+Q14+R14-2520)/21.75,2) -> 0 | V14: =ROUND(SUMIF(动态表!C:C,C14,动态表!AA:AA)+SUMIFS(其他补发!L:L,其他补发!B:B,C14),2) -> 0 | W14: =ROUND(VLOOKUP(C14,考勤!C:K,9,0)*P14/21.75/8*2+VLOOKUP(C14,考勤!C:L,10,0)*P14/21.75/8*3,2)+SUMIFS(加班费!$H:$H,加班费!$D:$D,$C14) -> 0 | X14: =SUMIF(奖金!D:D,C14,奖金!F:F) -> 0 | Y14: =SUMIF(其他补发!B:B,C14,其他补发!J:J) -> 0 | Z14: =SUMIF(其他补发!B:B,C14,其他补发!F:F) -> 0 | AA14: =SUMIF(其他补发!B:B,C14,其他补发!G:G) -> 0 | AB14: =SUMIF(其他补发!B:B,C14,其他补发!M:M) -> 0 | AC14: =SUMIF(其他补发!B:B,C14,其他补发!N:N) -> 0 | AD14: =SUMIF(其他补发!B:B,C14,其他补发!K:K) -> 0 | AE14: =AD14+AC14+AB14+AA14+Z14+Y14+X14+W14 -> 0 | AF14: =ROUND((P14+Q14+R14+S14+T14-U14-V14+AE14),2) -> 23000 | AG14: =SUMIF(税后扣款!B:B,C14,税后扣款!E:E) -> 0 | AH14: =SUMIF(房租水电!A:A,C14,房租水电!C:C) -> 0 | AI14: =SUMIF(房租水电!A:A,C14,房租水电!D:D) -> 0 | AJ14: =SUMIF(税后扣款!B:B,C14,税后扣款!D:D) -> -160 | AK14: =AJ14+AI14+AH14+AG14 -> -160 | AL14: =SUMIF(社会保险!D:D,N14,社会保险!I:I) -> 1840 | AM14: =SUMIF(社会保险!D:D,N14,社会保险!J:J) -> 460 | AN14: =SUMIF(社会保险!D:D,N14,社会保险!K:K) -> 46 | AO14: =SUMIF(公积金!C:C,N14,公积金!L:L) -> 1380 | AP14: =SUMIF(专项扣除!$B:$B,$C14,专项扣除!D:D) -> 0 | AQ14: =SUMIF(专项扣除!$B:$B,$C14,专项扣除!E:E) -> 0 | AR14: =SUMIF(专项扣除!$B:$B,$C14,专项扣除!F:F) -> 0 | AS14: =SUMIF(专项扣除!$B:$B,$C14,专项扣除!G:G) -> 0 | AT14: =SUMIF(专项扣除!$B:$B,$C14,专项扣除!H:H) -> 0 | AU14: =SUMIF(专项扣除!$B:$B,$C14,专项扣除!I:I) -> 0 | AV14: =SUMIF(专项扣除!$B:$B,$C14,专项扣除!J:J) -> 0 | AW14: 5000 | AX14: =AL14+AM14+AN14+AO14+AW14 -> 8726 | AY14: =SUMIF(上月累计工资累计社保和公积金!C:C,C14,上月累计工资累计社保和公积金!E:E) -> 161182.76 | AZ14: =IF(E14="实习人员",(AY14+AF14)*80%,AY14+AF14) -> 184182.76 | BA14: =SUMIF(上月累计工资累计社保和公积金!C:C,C14,上月累计工资累计社保和公积金!K:K) -> 61082 | BB14: =BA14+AX14 -> 69808 | BC14: =ROUND(MAX((AZ14-BB14-AP14-AQ14-AR14-AS14-AT14-AU14-AV14)*0.01*{3,10,20,25,30,35,45}-{0,2520,16920,31920,52920,85920,181920},0),2) -> 8917.48 | BD14: =SUMIF(上月累计工资累计社保和公积金!C:C,C14,上月累计工资累计社保和公积金!L:L) -> 7490.08 | BE14: =IF((BC14-BD14)<0,0,((BC14-BD14))) -> 1427.4 | BF14: =ROUND((AF14-AK14-BE14-AL14-AM14-AN14-AO14),2) -> 18006.6 | BH14: =VLOOKUP(C14,考勤!C:AL,36,0) -> ~@.com | BI14: =P14+Q14+R14+S14+T14-U14-V14+W14+X14+Y14+Z14+AA14+AB14+AC14+AD14-AG14-AH14-AI14-AJ14-AL14-AM14-AN14-AO14-BE14-BF14 -> 0
... A80: =ROW()-2 -> 78 | B80: 创想悦动 | C80: SCX00096 | D80: 谢琰 | E80: 实习人员 | F80: 创想悦动 | G80: 平台运营部 | H80: 46234 | J80: 创想悦动-销售 | K80: 材料科学与工程 | L80: 1 | M80: 创想悦动-销售 | N80: 441827200202063628 | O80: 6214833691023108 | P80: 4000 | Q80: =ROUND(SUMIF(其他补发!B:B,$C80,其他补发!D:D),2) -> 0 | R80: =ROUND(SUMIF(其他补发!B:B,$C80,其他补发!H:H),2) -> 0 | S80: =ROUND(SUMIF(其他补发!B:B,$C80,其他补发!I:I),2) -> 0 | T80: =ROUND(SUMIF(其他补发!B:B,$C80,其他补发!E:E),2) -> 0 | U80: =ROUND((VLOOKUP(C80,考勤!C:H,6,0)+VLOOKUP(C80,考勤!C:O,13,0)+VLOOKUP(C80,考勤!C:P,14,0)*0.3+VLOOKUP(C80,考勤!C:AA,25,0))*(P80+Q80+R80)/21.75,2)+ROUND((VLOOKUP(C80,考勤!C:V,19,0)+VLOOKUP(C80,考勤!C:V,20,0))*(P80+Q80+R80-2520)/21.75,2) -> 3816.09 | V80: =ROUND(SUMIF(动态表!C:C,C80,动态表!AA:AA)+SUMIFS(其他补发!L:L,其他补发!B:B,C80),2) -> 0 | W80: =ROUND(VLOOKUP(C80,考勤!C:K,9,0)*P80/21.75/8*2+VLOOKUP(C80,考勤!C:L,10,0)*P80/21.75/8*3,2)+SUMIFS(加班费!$H:$H,加班费!$D:$D,$C80) -> 0 | X80: =SUMIF(奖金!D:D,C80,奖金!F:F) -> 0 | Y80: =SUMIF(其他补发!B:B,C80,其他补发!J:J) -> 0 | Z80: =SUMIF(其他补发!B:B,C80,其他补发!F:F) -> 0 | AA80: =SUMIF(其他补发!B:B,C80,其他补发!G:G) -> 0 | AB80: =SUMIF(其他补发!B:B,C80,其他补发!M:M) -> 0 | AC80: =SUMIF(其他补发!B:B,C80,其他补发!N:N) -> 0 | AD80: =SUMIF(其他补发!B:B,C80,其他补发!K:K) -> 0 | AE80: =AD80+AC80+AB80+AA80+Z80+Y80+X80+W80 -> 0 | AF80: =ROUND((P80+Q80+R80+S80+T80-U80-V80+AE80),2) -> 183.91 | AG80: =SUMIF(税后扣款!B:B,C80,税后扣款!E:E) -> 0 | AH80: =SUMIF(房租水电!A:A,C80,房租水电!C:C) -> 0 | AI80: =SUMIF(房租水电!A:A,C80,房租水电!D:D) -> 0 | AJ80: =SUMIF(税后扣款!B:B,C80,税后扣款!D:D) -> 0 | AK80: =AJ80+AI80+AH80+AG80 -> 0 | AL80: =SUMIF(社会保险!D:D,N80,社会保险!I:I) -> 0 | AM80: =SUMIF(社会保险!D:D,N80,社会保险!J:J) -> 0 | AN80: =SUMIF(社会保险!D:D,N80,社会保险!K:K) -> 0 | AO80: =SUMIF(公积金!C:C,N80,公积金!L:L) -> 0 | AP80: =SUMIF(专项扣除!$B:$B,$C80,专项扣除!D:D) -> 0 | AQ80: =SUMIF(专项扣除!$B:$B,$C80,专项扣除!E:E) -> 0 | AR80: =SUMIF(专项扣除!$B:$B,$C80,专项扣除!F:F) -> 0 | AS80: =SUMIF(专项扣除!$B:$B,$C80,专项扣除!G:G) -> 0 | AT80: =SUMIF(专项扣除!$B:$B,$C80,专项扣除!H:H) -> 0 | AU80: =SUMIF(专项扣除!$B:$B,$C80,专项扣除!I:I) -> 0 | AV80: =SUMIF(专项扣除!$B:$B,$C80,专项扣除!J:J) -> 0 | AW80: 5000 | AX80: =AL80+AM80+AN80+AO80+AW80 -> 5000 | AY80: =SUMIF(上月累计工资累计社保和公积金!C:C,C80,上月累计工资累计社保和公积金!E:E) -> 0 | AZ80: =IF(E80="实习人员",(AY80+AF80)*80%,AY80+AF80) -> 147.128 | BA80: =SUMIF(上月累计工资累计社保和公积金!C:C,C80,上月累计工资累计社保和公积金!K:K) -> 0 | BB80: =BA80+AX80 -> 5000 | BC80: =ROUND(MAX((AZ80-BB80-AP80-AQ80-AR80-AS80-AT80-AU80-AV80)*0.01*{3,10,20,25,30,35,45}-{0,2520,16920,31920,52920,85920,181920},0),2) -> 0 | BD80: =SUMIF(上月累计工资累计社保和公积金!C:C,C80,上月累计工资累计社保和公积金!L:L) -> 0 | BE80: =IF((BC80-BD80)<0,0,((BC80-BD80))) -> 0 | BF80: =ROUND((AF80-AK80-BE80-AL80-AM80-AN80-AO80),2) -> 183.91 | BH80: =VLOOKUP(C80,考勤!C:AL,36,0) -> Wind@youdoogo.com | BI80: =P80+Q80+R80+S80+T80-U80-V80+W80+X80+Y80+Z80+AA80+AB80+AC80+AD80-AG80-AH80-AI80-AJ80-AL80-AM80-AN80-AO80-BE80-BF80 -> 0
A83: 总计 | L83: =SUM(L3:L82) -> 78 | P83: =SUM(SUM(P3:P82)) -> 1790300 | Q83: =SUM(SUM(Q3:Q82)) -> 0 | R83: =SUM(SUM(R3:R82)) -> 0 | S83: =SUM(SUM(S3:S82)) -> 0 | T83: =SUM(SUM(T3:T82)) -> 0 | U83: =SUM(SUM(U3:U82)) -> 49494.26 | V83: =SUM(SUM(V3:V82)) -> 0 | W83: =SUM(SUM(W3:W82)) -> 0 | ... BF83: =SUM(SUM(BF3:BF82)) -> 1329965.5 | BI83: =P83+Q83+R83+S83+T83-U83-V83+W83+X83+Y83+Z83+AA83+AB83+AC83+AD83-AG83-AH83-AI83-AJ83-AL83-AM83-AN83-AO83-BE83-BF83 -> 0
B87: 制表： | H87: 财务部： | R87: 人力资源部总监审批： | Y87: 财务部总监审批： | AG87: 审批： | AO87: 审批：
F92: 总体检查 | P92: =P83-汇总!D9 -> 0 | Q92: =Q83-汇总!E9 -> 0 | R92: =R83-汇总!F9 -> 0 | S92: =S83-汇总!G9 -> 0 | T92: =T83-汇总!H9 -> 0 | U92: =U83-汇总!I9 -> 0 | V92: =V83-汇总!J9 -> 0 | W92: =W83-汇总!K9 -> 0 | ... AO92: =AO83-汇总!AC9 -> 0 | BE92: =BE83-汇总!AD9 -> 0 | BF92: =BF83-汇总!AE9 -> 0
B98: 原人数 | C98: 76
B99: 6月表往月离职需要发放 | C99: 0
B100: 6月离职 | C100: 4
B101: 7月入职 | C101: 6
B102: 往月离职需发薪 | C102: 0
B103: 校招生月中换合同 | C103: 0
B105: 当月人数合计 | C105: =C98-C99-C100+C101+C102-C103 -> 78
C107: =C98+C101-C100-C105 -> 0

Sheet 离职补偿-创想悦动
A1: 深圳创想悦动科技有限公司2026年7月离职补偿表
A2: 序号 | B2: 工号 | C2: 姓名 | D2: 组队 | E2: 成本中心 | F2: 卡号 | G2: 离职补偿金 | H2: 所得税 | I2: 其他扣款 | J2: 实发补偿金 | K2: 备注 | L2: 免税额 | M2: 应纳税额度
A3: 1 | D3: =VLOOKUP($B3,工资表明细!$C$2:$O$146,4,0) -> 0 | E3: =VLOOKUP($B3,工资表明细!$C$2:$O$146,11,0) -> 0 | F3: =VLOOKUP($B3,工资表明细!$C$2:$O$146,13,0) -> 0 | H3: =ROUND(MAX((M3)*0.01*{3,10,20,25,30,35,45}-{0,2520,16920,31920,52920,85920,181920},0),2) -> 0 | I3: 0 | J3: =G3-H3-I3 -> 0 | L3: 494262 | M3: =IF(G3-L3>0,G3-L3,0) -> 0
A4: 合计 | G4: =SUM(G3:G3) -> 0 | H4: =SUM(H3:H3) -> 0 | I4: =SUM(I3:I3) -> 0 | J4: =SUM(J3:J3) -> 0
A10: 制表：黄晓彤 | C10: 财务部：俞光武 | E10: 审批：金美娜 | G10: 审批：王茵 | I10: 审批：刘丹 | K10: 审批：赫旋

Sheet 动态表
T1: 1 | U1: 1 | Y1: 公式有调整，含绩效部分 | Z1: 1 | AA1: 基本工资+绩效工资扣款
A2: 序号 | B2: 公司 | C2: 工号 | D2: 姓名 | E2: 一级部门 | F2: 二级部门 | G2: 职位 | H2: 动态类型 | L2: 薪酬执行标准 | T2: 缺勤天数 | U2: 剩余结算年假天数 | V2: 剩余结算加班小时数 | W2: 变动日期 | X2: 备注 | Y2: 工资涨幅 | Z2: 变更前天数 | AA2: 扣款金额 | AB2: 身份证号码 | AC2: 工资卡号 | AD2: 手机号码 | AF2: 姓名检查1 | AG2: 检查
H3: 入职 | I3: 转正 | J3: 离职 | K3: 异动 | L3: 原薪资 | M3: 原岗位津贴 | N3: 现薪资 | O3: 现岗位津贴 | P3: 转正后薪资 | Q3: 转正后岗位津贴 | R3: 补发/扣发金额 | S3: 离职补偿 | AI3: 工资检查1 | AJ3: 校验 | AK3: 岗位津贴检查1 | AL3: 校验 | AM3: 入离职缺勤天数 | AN3: 校验 | AO3: 出现次数
A4: 1 | B4: 创想悦动 | C4: SCX00089 | D4: 麦汝琪 | E4: 创想悦动 | F4: 营销合作部 | G4: 商务经理 | H4: √ | N4: 8000 | P4: 8000 | T4: 0 | W4: 46204 | Y4: =IF(L4>0,(N4+O4)-(L4+M4),0) -> 0 | Z4: 0 | AA4: =ROUND(Y4/21.75*Z4,2) -> 0 | AB4: =VLOOKUP(C4,考勤!C:AH,32,0) -> 440306200211143224 | AC4: =VLOOKUP(C4,考勤!C:AI,33,0) -> 6214837889289025 | AD4: =VLOOKUP(C4,考勤!C:AK,35,0) -> 18123802382 | AF4: =VLOOKUP(C4,考勤!C:F,2,0) -> 麦汝琪 | AG4: =IF(D4=AF4,1) -> 1 | AI4: =VLOOKUP(C4,工资表明细!$C$2:$P$322,14,0) -> 8000 | AJ4: =AI4-N4 -> 0 | AK4: =VLOOKUP($C4,工资表明细!$C$2:$BF$322,16,0) -> 0 | AL4: =AK4-Q4 -> 0 | AM4: =VLOOKUP(C4,考勤!$C$2:$H$100,6,0) -> 0 | AN4: =AM4-T4 -> 0 | AO4: =COUNTIF(C:C,C4) -> 1
